Workbook
Name UPDATE: 'Data Sheet'!$E$1

Sheet HistoricalFS
B2: ="Historical Statement - " & 'Data Sheet'!B1 -> Historical Statement - ITC LTD
B3: Years | C3: =IFERROR('Data Sheet'!B16,0) -> 42825 | D3: =IFERROR('Data Sheet'!C16,0) -> 43190 | E3: =IFERROR('Data Sheet'!D16,0) -> 43555 | F3: =IFERROR('Data Sheet'!E16,0) -> 43921 | G3: =IFERROR('Data Sheet'!F16,0) -> 44286 | H3: =IFERROR('Data Sheet'!G16,0) -> 44651 | I3: =IFERROR('Data Sheet'!H16,0) -> 45016 | J3: =IFERROR('Data Sheet'!I16,0) -> 45382 | ... L3: =IFERROR('Data Sheet'!K16,0) -> 46112 | M3: LTM
A5: # | B5: Income Statement
B6: Sales | C6: =IFERROR('Data Sheet'!B17,0) -> 42767.6 | D6: =IFERROR('Data Sheet'!C17,0) -> 43448.94 | E6: =IFERROR('Data Sheet'!D17,0) -> 48339.58 | F6: =IFERROR('Data Sheet'!E17,0) -> 49387.7 | G6: =IFERROR('Data Sheet'!F17,0) -> 49257.45 | H6: =IFERROR('Data Sheet'!G17,0) -> 60644.54 | I6: =IFERROR('Data Sheet'!H17,0) -> 70919.03 | J6: =IFERROR('Data Sheet'!I17,0) -> 67931.94 | ... L6: =IFERROR('Data Sheet'!K17,0) -> 78868.4 | M6: =IFERROR(SUM('Data Sheet'!H42:K42),0) -> 78868.4
B7: Sales Growth | C7: - | D7: =D6/C6-1 -> 0.015931219 | E7: =E6/D6-1 -> 0.11256063 | F7: =F6/E6-1 -> 0.021682439 | G7: =G6/F6-1 -> -0.0026372963 | H7: =H6/G6-1 -> 0.23117498 | I7: =I6/H6-1 -> 0.16942152 | J7: =J6/I6-1 -> -0.042119724 | K7: =K6/J6-1 -> 0.10880596 | L7: =L6/K6-1 -> 0.047064562 | M7: -
B9: COS | C9: =IFERROR(SUM('Data Sheet'!B20:B22)-1*'Data Sheet'!B19,0) -> 6492.53 | D9: =IFERROR(SUM('Data Sheet'!C20:C22)-1*'Data Sheet'!C19,0) -> 7139.78 | E9: =IFERROR(SUM('Data Sheet'!D20:D22)-1*'Data Sheet'!D19,0) -> 6592.43 | F9: =IFERROR(SUM('Data Sheet'!E20:E22)-1*'Data Sheet'!E19,0) -> 6281.8 | G9: =IFERROR(SUM('Data Sheet'!F20:F22)-1*'Data Sheet'!F19,0) -> 6104.8 | H9: =IFERROR(SUM('Data Sheet'!G20:G22)-1*'Data Sheet'!G19,0) -> 6981.99 | I9: =IFERROR(SUM('Data Sheet'!H20:H22)-1*'Data Sheet'!H19,0) -> 8937.77 | J9: =IFERROR(SUM('Data Sheet'!I20:I22)-1*'Data Sheet'!I19,0) -> 8317.42 | ... L9: =IFERROR(SUM('Data Sheet'!K20:K22)-1*'Data Sheet'!K19,0) -> 7761.23 | M9: =IFERROR(SUM('Data Sheet'!H43:K43),0) -> 51550.49
B10: COS % Sales | C10: =C9/C6 -> 0.15180955 | D10: =D9/D6 -> 0.16432576 | E10: =E9/E6 -> 0.13637748 | F10: =F9/F6 -> 0.12719361 | G10: =G9/G6 -> 0.12393658 | H10: =H9/H6 -> 0.11512974 | I10: =I9/I6 -> 0.12602781 | J10: =J9/J6 -> 0.12243755 | ... M10: =M9/M6 -> 0.65362667
B12: Gross Profit | C12: =C6-C9 -> 36275.07 | D12: =D6-D9 -> 36309.16 | E12: =E6-E9 -> 41747.15 | F12: =F6-F9 -> 43105.9 | G12: =G6-G9 -> 43152.65 | H12: =H6-H9 -> 53662.55 | I12: =I6-I9 -> 61981.26 | J12: =J6-J9 -> 59614.52 | ... M12: =M6-M9 -> 27317.91
B13: Gross Margins | C13: =C12/C6 -> 0.84819045 | D13: =D12/D6 -> 0.83567424 | E13: =E12/E6 -> 0.86362252 | F13: =F12/F6 -> 0.87280639 | G13: =G12/G6 -> 0.87606342 | H13: =H12/H6 -> 0.88487026 | I13: =I12/I6 -> 0.87397219 | J13: =J12/J6 -> 0.87756245 | ... M13: =M12/M6 -> 0.34637333
B15: Selling & General Expenses | C15: =IFERROR(SUM('Data Sheet'!B23:B24),0) -> 5348.97 | D15: =IFERROR(SUM('Data Sheet'!C23:C24),0) -> 4960.85 | E15: =IFERROR(SUM('Data Sheet'!D23:D24),0) -> 5586.24 | F15: =IFERROR(SUM('Data Sheet'!E23:E24),0) -> 5713.76 | G15: =IFERROR(SUM('Data Sheet'!F23:F24),0) -> 5311.16 | H15: =IFERROR(SUM('Data Sheet'!G23:G24),0) -> 5968.33 | I15: =IFERROR(SUM('Data Sheet'!H23:H24),0) -> 6912.64 | J15: =IFERROR(SUM('Data Sheet'!I23:I24),0) -> 7078.42 | ... L15: =IFERROR(SUM('Data Sheet'!K23:K24),0) -> 8702.83
B16: SG&A % Sales | C16: =C15/C6 -> 0.12507061 | D16: =D15/D6 -> 0.11417655 | E16: =E15/E6 -> 0.11556244 | F16: =F15/F6 -> 0.11569196 | G16: =G15/G6 -> 0.1078245 | H16: =H15/H6 -> 0.09841496 | I16: =I15/I6 -> 0.097472286 | J16: =J15/J6 -> 0.1041987 | ... M16: =M15/M6 -> 0
B18: EBITDA | C18: =C12-C15 -> 30926.1 | D18: =D12-D15 -> 31348.31 | E18: =E12-E15 -> 36160.91 | F18: =F12-F15 -> 37392.14 | G18: =G12-G15 -> 37841.49 | H18: =H12-H15 -> 47694.22 | I18: =I12-I15 -> 55068.62 | J18: =J12-J15 -> 52536.1 | ... M18: =M12-M15 -> 27317.91
B19: EBITDA % Sales | C19: =C18/C6 -> 0.72311984 | D19: =D18/D6 -> 0.72149769 | E19: =E18/E6 -> 0.74806008 | F19: =F18/F6 -> 0.75711442 | G19: =G18/G6 -> 0.76823892 | H19: =H18/H6 -> 0.7864553 | I19: =I18/I6 -> 0.7764999 | J19: =J18/J6 -> 0.77336375 | ... M19: =M18/M6 -> 0.34637333
B21: Interest | C21: =IFERROR(('Data Sheet'!B27),0) -> 49.03 | D21: =IFERROR(('Data Sheet'!C27),0) -> 115.01 | E21: =IFERROR(('Data Sheet'!D27),0) -> 71.4 | F21: =IFERROR(('Data Sheet'!E27),0) -> 81.38 | G21: =IFERROR(('Data Sheet'!F27),0) -> 57.97 | H21: =IFERROR(('Data Sheet'!G27),0) -> 59.99 | I21: =IFERROR(('Data Sheet'!H27),0) -> 77.77 | J21: =IFERROR(('Data Sheet'!I27),0) -> 39.11 | ... L21: =IFERROR(('Data Sheet'!K27),0) -> 85.17 | M21: =IFERROR(SUM('Data Sheet'!H46:K46),0) -> 85.17
B22: Interest % Sales | C22: =C21/C6 -> 0.0011464286 | D22: =D21/D6 -> 0.0026470151 | E22: =E21/E6 -> 0.0014770505 | F22: =F21/F6 -> 0.0016477787 | G22: =G21/G6 -> 0.0011768778 | H22: =H21/H6 -> 0.00098920694 | I22: =I21/I6 -> 0.0010966027 | J22: =J21/J6 -> 0.00057572329 | ... M22: =M21/M6 -> 0.0010799002
B24: Depreciation | C24: =IFERROR(('Data Sheet'!B26),0) -> 1152.79 | D24: =IFERROR(('Data Sheet'!C26),0) -> 1236.28 | E24: =IFERROR(('Data Sheet'!D26),0) -> 1396.61 | F24: =IFERROR(('Data Sheet'!E26),0) -> 1644.91 | G24: =IFERROR(('Data Sheet'!F26),0) -> 1645.59 | H24: =IFERROR(('Data Sheet'!G26),0) -> 1732.41 | I24: =IFERROR(('Data Sheet'!H26),0) -> 1809.01 | J24: =IFERROR(('Data Sheet'!I26),0) -> 1518.05 | ... L24: =IFERROR(('Data Sheet'!K26),0) -> 1710.53 | M24: =IFERROR(SUM('Data Sheet'!H45:K45),0) -> 1710.53
B25: Depreciation % Sales | C25: =C24/C6 -> 0.026954751 | D25: =D24/D6 -> 0.028453629 | E25: =E24/E6 -> 0.028891645 | F25: =F24/F6 -> 0.033306066 | G25: =G24/G6 -> 0.033407941 | H25: =H24/H6 -> 0.028566628 | I25: =I24/I6 -> 0.025508104 | J25: =J24/J6 -> 0.022346631 | ... M25: =M24/M6 -> 0.021688408
B27: Earnings Before Tax | C27: =IFERROR(C18-SUM(C21,C24),0) -> 29724.28 | D27: =IFERROR(D18-SUM(D21,D24),0) -> 29997.02 | E27: =IFERROR(E18-SUM(E21,E24),0) -> 34692.9 | F27: =IFERROR(F18-SUM(F21,F24),0) -> 35665.85 | G27: =IFERROR(G18-SUM(G21,G24),0) -> 36137.93 | H27: =IFERROR(H18-SUM(H21,H24),0) -> 45901.82 | I27: =IFERROR(I18-SUM(I21,I24),0) -> 53181.84 | J27: =IFERROR(J18-SUM(J21,J24),0) -> 50978.94 | ... M27: =IFERROR(M18-SUM(M21,M24),0) -> 25522.21
B28: EBT % Sales | C28: =C27/C6 -> 0.69501866 | D28: =D27/D6 -> 0.69039705 | E28: =E27/E6 -> 0.71769138 | F28: =F27/F6 -> 0.72216058 | G28: =G27/G6 -> 0.7336541 | H28: =H27/H6 -> 0.75689947 | I28: =I27/I6 -> 0.7498952 | J28: =J27/J6 -> 0.7504414 | ... M28: =M27/M6 -> 0.32360502
B30: Tax | C30: =IFERROR('Data Sheet'!B29,0) -> 5549.09 | D30: =IFERROR('Data Sheet'!C29,0) -> 5916.43 | E30: =IFERROR('Data Sheet'!D29,0) -> 6313.92 | F30: =IFERROR('Data Sheet'!E29,0) -> 4441.79 | G30: =IFERROR('Data Sheet'!F29,0) -> 4555.29 | H30: =IFERROR('Data Sheet'!G29,0) -> 5237.34 | I30: =IFERROR('Data Sheet'!H29,0) -> 6438.4 | J30: =IFERROR('Data Sheet'!I29,0) -> 6209.46 | ... L30: =IFERROR('Data Sheet'!K29,0) -> 7015.24 | M30: =IFERROR(SUM('Data Sheet'!H48:K48),0) -> 7015.24
B31: Effective Tax rate | C31: =C30/C27 -> 0.18668543 | D31: =D30/D27 -> 0.19723393 | E31: =E30/E27 -> 0.18199459 | F31: =F30/F27 -> 0.12453902 | G31: =G30/G27 -> 0.12605288 | H31: =H30/H27 -> 0.11409874 | I31: =I30/I27 -> 0.12106388 | J31: =J30/J27 -> 0.12180442 | ... M31: =M30/M27 -> 0.27486805
B33: Net Profit | C33: =IFERROR((C27-C30),0) -> 24175.19 | D33: =IFERROR((D27-D30),0) -> 24080.59 | E33: =IFERROR((E27-E30),0) -> 28378.98 | F33: =IFERROR((F27-F30),0) -> 31224.06 | G33: =IFERROR((G27-G30),0) -> 31582.64 | H33: =IFERROR((H27-H30),0) -> 40664.48 | I33: =IFERROR((I27-I30),0) -> 46743.44 | J33: =IFERROR((J27-J30),0) -> 44769.48 | ... M33: =IFERROR((M27-M30),0) -> 18506.97
B34: Net Margin | C34: =C33/C6 -> 0.5652688 | D34: =D33/D6 -> 0.55422733 | E34: =E33/E6 -> 0.58707544 | F34: =F33/F6 -> 0.63222341 | G34: =G33/G6 -> 0.64117489 | H34: =H33/H6 -> 0.67053819 | I34: =I33/I6 -> 0.65910997 | J34: =J33/J6 -> 0.65903432 | ... M34: =M33/M6 -> 0.23465634
B36: No. of Equity Shares O/S | C36: =IFERROR('Data Sheet'!B93,0) -> 1214.74 | D36: =IFERROR('Data Sheet'!C93,0) -> 1220.43 | E36: =IFERROR('Data Sheet'!D93,0) -> 1225.86 | F36: =IFERROR('Data Sheet'!E93,0) -> 1229.22 | G36: =IFERROR('Data Sheet'!F93,0) -> 1230.88 | H36: =IFERROR('Data Sheet'!G93,0) -> 1232.33 | I36: =IFERROR('Data Sheet'!H93,0) -> 1242.8 | J36: =IFERROR('Data Sheet'!I93,0) -> 1248.47 | ... L36: =IFERROR('Data Sheet'!K93,0) -> 1252.95 | M36: =L36 -> 1252.95
B38: Earnings Per Share | C38: =IFERROR(C33/C36,0) -> 19.901534 | D38: =IFERROR(D33/D36,0) -> 19.731234 | E38: =IFERROR(E33/E36,0) -> 23.150262 | F38: =IFERROR(F33/F36,0) -> 25.401523 | G38: =IFERROR(G33/G36,0) -> 25.658586 | H38: =IFERROR(H33/H36,0) -> 32.998044 | I38: =IFERROR(I33/I36,0) -> 37.611394 | J38: =IFERROR(J33/J36,0) -> 35.859476 | ... M38: =IFERROR(M33/M36,0) -> 14.770717
B39: EPS growth % | D39: =IFERROR((D38/C38-1),0) -> -0.0085571498 | E39: =IFERROR((E38/D38-1),0) -> 0.17327998 | F39: =IFERROR((F38/E38-1),0) -> 0.097245598 | G39: =IFERROR((G38/F38-1),0) -> 0.010119976 | H39: =IFERROR((H38/G38-1),0) -> 0.28604299 | I39: =IFERROR((I38/H38-1),0) -> 0.13980675 | J39: =IFERROR((J38/I38-1),0) -> -0.046579439 | K39: =IFERROR((K38/J38-1),0) -> 0.1131856 | ... M39: =IFERROR((M38/L38-1),0) -> -0.65467819
B41: Dividends Per Share | C41: =IFERROR(('Data Sheet'!B31/C36),0) -> 4.7500041 | D41: =IFERROR(('Data Sheet'!C31/D36),0) -> 5.1499963 | E41: =IFERROR(('Data Sheet'!D31/E36),0) -> 5.7500041 | F41: =IFERROR(('Data Sheet'!E31/F36),0) -> 10.149998 | G41: =IFERROR(('Data Sheet'!F31/G36),0) -> 10.75 | H41: =IFERROR(('Data Sheet'!G31/H36),0) -> 11.500004 | I41: =IFERROR(('Data Sheet'!H31/I36),0) -> 15.5 | J41: =IFERROR(('Data Sheet'!I31/J36),0) -> 13.749998 | ... M41: =IFERROR(('Data Sheet'!L31/M36),0) -> 0
B42: Dividend Payout Ratio | C42: =IFERROR((C41/C38),0) -> 0.23867527 | D42: =IFERROR((D41/D38),0) -> 0.26100731 | E42: =IFERROR((E41/E38),0) -> 0.2483775 | F42: =IFERROR((F41/F38),0) -> 0.39958225 | G42: =IFERROR((G41/G38),0) -> 0.41896308 | H42: =IFERROR((H41/H38),0) -> 0.34850562 | I42: =IFERROR((I41/I38),0) -> 0.41210916 | J42: =IFERROR((J41/J38),0) -> 0.38344113 | ... M42: =IFERROR((M41/M38),0) -> 0
B44: Retained Earnings | C44: =IFERROR(IF(C38>C41,1-C42,0),0) -> 0.76132473 | D44: =IFERROR(IF(D38>D41,1-D42,0),0) -> 0.73899269 | E44: =IFERROR(IF(E38>E41,1-E42,0),0) -> 0.7516225 | F44: =IFERROR(IF(F38>F41,1-F42,0),0) -> 0.60041775 | G44: =IFERROR(IF(G38>G41,1-G42,0),0) -> 0.58103692 | H44: =IFERROR(IF(H38>H41,1-H42,0),0) -> 0.65149438 | I44: =IFERROR(IF(I38>I41,1-I42,0),0) -> 0.58789084 | J44: =IFERROR(IF(J38>J41,1-J42,0),0) -> 0.61655887 | ... M44: =IFERROR(IF(M38>M41,1-M42,0),0) -> 1
A46: # | B46: Balance Sheet
B47: Equity Share Capital | C47: =IFERROR('Data Sheet'!B57,0) -> 1214.74 | D47: =IFERROR('Data Sheet'!C57,0) -> 1220.43 | E47: =IFERROR('Data Sheet'!D57,0) -> 1225.86 | F47: =IFERROR('Data Sheet'!E57,0) -> 1229.22 | G47: =IFERROR('Data Sheet'!F57,0) -> 1230.88 | H47: =IFERROR('Data Sheet'!G57,0) -> 1232.33 | I47: =IFERROR('Data Sheet'!H57,0) -> 1242.8 | J47: =IFERROR('Data Sheet'!I57,0) -> 1248.47 | ... L47: =IFERROR('Data Sheet'!K57,0) -> 1252.95
B48: Reserves | C48: =IFERROR('Data Sheet'!B58,0) -> 45198.19 | D48: =IFERROR('Data Sheet'!C58,0) -> 51289.68 | E48: =IFERROR('Data Sheet'!D58,0) -> 57915.01 | F48: =IFERROR('Data Sheet'!E58,0) -> 64044.04 | G48: =IFERROR('Data Sheet'!F58,0) -> 59116.46 | H48: =IFERROR('Data Sheet'!G58,0) -> 61223.24 | I48: =IFERROR('Data Sheet'!H58,0) -> 67912.46 | J48: =IFERROR('Data Sheet'!I58,0) -> 73258.53 | ... L48: =IFERROR('Data Sheet'!K58,0) -> 71254.35
B49: Borrowings | C49: =IFERROR('Data Sheet'!B59,0) -> 45.72 | D49: =IFERROR('Data Sheet'!C59,0) -> 35.92 | E49: =IFERROR('Data Sheet'!D59,0) -> 13.44 | F49: =IFERROR('Data Sheet'!E59,0) -> 277.45 | G49: =IFERROR('Data Sheet'!F59,0) -> 270.83 | H49: =IFERROR('Data Sheet'!G59,0) -> 249.44 | I49: =IFERROR('Data Sheet'!H59,0) -> 306.04 | J49: =IFERROR('Data Sheet'!I59,0) -> 303.43 | ... L49: =IFERROR('Data Sheet'!K59,0) -> 2399.06
B50: Other Liabilities | C50: =IFERROR('Data Sheet'!B60,0) -> 9439.67 | D50: =IFERROR('Data Sheet'!C60,0) -> 11694.85 | E50: =IFERROR('Data Sheet'!D60,0) -> 12584.73 | F50: =IFERROR('Data Sheet'!E60,0) -> 11760.04 | G50: =IFERROR('Data Sheet'!F60,0) -> 13142.59 | H50: =IFERROR('Data Sheet'!G60,0) -> 14491.01 | I50: =IFERROR('Data Sheet'!H60,0) -> 16369.66 | J50: =IFERROR('Data Sheet'!I60,0) -> 16943.54 | ... L50: =IFERROR('Data Sheet'!K60,0) -> 18730.84
B51: Total Liabilities | C51: =IFERROR('Data Sheet'!B61,0) -> 55898.32 | D51: =IFERROR('Data Sheet'!C61,0) -> 64240.88 | E51: =IFERROR('Data Sheet'!D61,0) -> 71739.04 | F51: =IFERROR('Data Sheet'!E61,0) -> 77310.75 | G51: =IFERROR('Data Sheet'!F61,0) -> 73760.76 | H51: =IFERROR('Data Sheet'!G61,0) -> 77196.02 | I51: =IFERROR('Data Sheet'!H61,0) -> 85830.96 | J51: =IFERROR('Data Sheet'!I61,0) -> 91753.97 | ... L51: =IFERROR('Data Sheet'!K61,0) -> 93637.2
B53: Fixed Assets Net Block | C53: =IFERROR('Data Sheet'!B62,0) -> 15893.48 | D53: =IFERROR('Data Sheet'!C62,0) -> 16523.96 | E53: =IFERROR('Data Sheet'!D62,0) -> 19374.19 | F53: =IFERROR('Data Sheet'!E62,0) -> 21713.34 | G53: =IFERROR('Data Sheet'!F62,0) -> 23298.48 | H53: =IFERROR('Data Sheet'!G62,0) -> 24231.59 | I53: =IFERROR('Data Sheet'!H62,0) -> 25851.27 | J53: =IFERROR('Data Sheet'!I62,0) -> 27820.22 | ... L53: =IFERROR('Data Sheet'!K62,0) -> 22442.53
B54: Capital Work in Progress | C54: =IFERROR('Data Sheet'!B63,0) -> 3729.89 | D54: =IFERROR('Data Sheet'!C63,0) -> 5508.33 | E54: =IFERROR('Data Sheet'!D63,0) -> 4136.42 | F54: =IFERROR('Data Sheet'!E63,0) -> 3256.46 | G54: =IFERROR('Data Sheet'!F63,0) -> 4011.29 | H54: =IFERROR('Data Sheet'!G63,0) -> 3225.54 | I54: =IFERROR('Data Sheet'!H63,0) -> 3003.3 | J54: =IFERROR('Data Sheet'!I63,0) -> 2860.78 | ... L54: =IFERROR('Data Sheet'!K63,0) -> 1601.88
B55: Investments | C55: =IFERROR('Data Sheet'!B64,0) -> 17581.38 | D55: =IFERROR('Data Sheet'!C64,0) -> 22052.86 | E55: =IFERROR('Data Sheet'!D64,0) -> 25043.49 | F55: =IFERROR('Data Sheet'!E64,0) -> 28663.35 | G55: =IFERROR('Data Sheet'!F64,0) -> 24870.87 | H55: =IFERROR('Data Sheet'!G64,0) -> 24841.01 | I55: =IFERROR('Data Sheet'!H64,0) -> 29415.02 | J55: =IFERROR('Data Sheet'!I64,0) -> 31114.02 | ... L55: =IFERROR('Data Sheet'!K64,0) -> 38128.43
B56: Other Assets | C56: =IFERROR('Data Sheet'!B65-SUM('Data Sheet'!B67:B69),0) -> 5135.78 | D56: =IFERROR('Data Sheet'!C65-SUM('Data Sheet'!C67:C69),0) -> 7078.75 | E56: =IFERROR('Data Sheet'!D65-SUM('Data Sheet'!D67:D69),0) -> 7138.07 | F56: =IFERROR('Data Sheet'!E65-SUM('Data Sheet'!E67:E69),0) -> 4958.45 | G56: =IFERROR('Data Sheet'!F65-SUM('Data Sheet'!F67:F69),0) -> 4022.24 | H56: =IFERROR('Data Sheet'!G65-SUM('Data Sheet'!G67:G69),0) -> 6917.41 | I56: =IFERROR('Data Sheet'!H65-SUM('Data Sheet'!H67:H69),0) -> 7953.85 | J56: =IFERROR('Data Sheet'!I65-SUM('Data Sheet'!I67:I69),0) -> 4562.57 | ... L56: =IFERROR('Data Sheet'!K65-SUM('Data Sheet'!K67:K69),0) -> 5909.75
B57: Total Non Current Asset | C57: =IFERROR(SUM(C53:C56),0) -> 42340.53 | D57: =IFERROR(SUM(D53:D56),0) -> 51163.9 | E57: =IFERROR(SUM(E53:E56),0) -> 55692.17 | F57: =IFERROR(SUM(F53:F56),0) -> 58591.6 | G57: =IFERROR(SUM(G53:G56),0) -> 56202.88 | H57: =IFERROR(SUM(H53:H56),0) -> 59215.55 | I57: =IFERROR(SUM(I53:I56),0) -> 66223.44 | J57: =IFERROR(SUM(J53:J56),0) -> 66357.59 | ... L57: =IFERROR(SUM(L53:L56),0) -> 68082.59
...

Sheet Ratio Analysis
B2: ="Ratio Analysis - " & 'Data Sheet'!B1 -> Ratio Analysis - ITC LTD
B3: Years | C3: =IFERROR('Data Sheet'!B16,0) -> 42825 | D3: =IFERROR('Data Sheet'!C16,0) -> 43190 | E3: =IFERROR('Data Sheet'!D16,0) -> 43555 | F3: =IFERROR('Data Sheet'!E16,0) -> 43921 | G3: =IFERROR('Data Sheet'!F16,0) -> 44286 | H3: =IFERROR('Data Sheet'!G16,0) -> 44651 | I3: =IFERROR('Data Sheet'!H16,0) -> 45016 | J3: =IFERROR('Data Sheet'!I16,0) -> 45382 | ... L3: =IFERROR('Data Sheet'!K16,0) -> 46112 | M3: LTM | N3: Trend | O3: Mean | P3: Median
B5: Sales growth | D5: =IFERROR(HistoricalFS!D7,0) -> 0.015931219 | E5: =IFERROR(HistoricalFS!E7,0) -> 0.11256063 | F5: =IFERROR(HistoricalFS!F7,0) -> 0.021682439 | G5: =IFERROR(HistoricalFS!G7,0) -> -0.0026372963 | H5: =IFERROR(HistoricalFS!H7,0) -> 0.23117498 | I5: =IFERROR(HistoricalFS!I7,0) -> 0.16942152 | J5: =IFERROR(HistoricalFS!J7,0) -> -0.042119724 | K5: =IFERROR(HistoricalFS!K7,0) -> 0.10880596 | L5: =IFERROR(HistoricalFS!L7,0) -> 0.047064562 | O5: =IFERROR(AVERAGE(D5:L5),0) -> 0.073542698 | P5: =IFERROR(MEDIAN(C5:L5),0) -> 0.047064562
B6: EBITDA growth | D6: =IFERROR(HistoricalFS!D18/HistoricalFS!C18-1,0) -> 0.013652223 | E6: =IFERROR(HistoricalFS!E18/HistoricalFS!D18-1,0) -> 0.15352024 | F6: =IFERROR(HistoricalFS!F18/HistoricalFS!E18-1,0) -> 0.034048645 | G6: =IFERROR(HistoricalFS!G18/HistoricalFS!F18-1,0) -> 0.012017231 | H6: =IFERROR(HistoricalFS!H18/HistoricalFS!G18-1,0) -> 0.26036845 | I6: =IFERROR(HistoricalFS!I18/HistoricalFS!H18-1,0) -> 0.15461832 | J6: =IFERROR(HistoricalFS!J18/HistoricalFS!I18-1,0) -> -0.045988441 | K6: =IFERROR(HistoricalFS!K18/HistoricalFS!J18-1,0) -> 0.11420433 | L6: =IFERROR(HistoricalFS!L18/HistoricalFS!K18-1,0) -> 0.066085713 | O6: =IFERROR(AVERAGE(D6:L6),0) -> 0.084725189 | P6: =IFERROR(MEDIAN(C6:L6),0) -> 0.066085713
B7: EBIT growth | D7: =IFERROR((HistoricalFS!D18-HistoricalFS!D24)/(HistoricalFS!C18-HistoricalFS!C24)-1,0) -> 0.011376632 | E7: =IFERROR((HistoricalFS!E18-HistoricalFS!E24)/(HistoricalFS!D18-HistoricalFS!D24)-1,0) -> 0.15449872 | F7: =IFERROR((HistoricalFS!F18-HistoricalFS!F24)/(HistoricalFS!E18-HistoricalFS!E24)-1,0) -> 0.02827412 | G7: =IFERROR((HistoricalFS!G18-HistoricalFS!G24)/(HistoricalFS!F18-HistoricalFS!F24)-1,0) -> 0.012551182 | H7: =IFERROR((HistoricalFS!H18-HistoricalFS!H24)/(HistoricalFS!G18-HistoricalFS!G24)-1,0) -> 0.26980708 | I7: =IFERROR((HistoricalFS!I18-HistoricalFS!I24)/(HistoricalFS!H18-HistoricalFS!H24)-1,0) -> 0.15877965 | J7: =IFERROR((HistoricalFS!J18-HistoricalFS!J24)/(HistoricalFS!I18-HistoricalFS!I24)-1,0) -> -0.042087428 | K7: =IFERROR((HistoricalFS!K18-HistoricalFS!K24)/(HistoricalFS!J18-HistoricalFS!J24)-1,0) -> 0.11508829 | L7: =IFERROR((HistoricalFS!L18-HistoricalFS!L24)/(HistoricalFS!K18-HistoricalFS!K24)-1,0) -> 0.06686948 | O7: =IFERROR(AVERAGE(D7:L7),0) -> 0.086128635 | P7: =IFERROR(MEDIAN(C7:L7),0) -> 0.06686948
B8: Net profit growth | D8: =IFERROR(HistoricalFS!D33/HistoricalFS!C33-1,0) -> -0.0039131026 | E8: =IFERROR(HistoricalFS!E33/HistoricalFS!D33-1,0) -> 0.17850019 | F8: =IFERROR(HistoricalFS!F33/HistoricalFS!E33-1,0) -> 0.10025307 | G8: =IFERROR(HistoricalFS!G33/HistoricalFS!F33-1,0) -> 0.011484093 | H8: =IFERROR(HistoricalFS!H33/HistoricalFS!G33-1,0) -> 0.28755797 | I8: =IFERROR(HistoricalFS!I33/HistoricalFS!H33-1,0) -> 0.14949066 | J8: =IFERROR(HistoricalFS!J33/HistoricalFS!I33-1,0) -> -0.042229669 | K8: =IFERROR(HistoricalFS!K33/HistoricalFS!J33-1,0) -> 0.11580702 | L8: =IFERROR(HistoricalFS!L33/HistoricalFS!K33-1,0) -> 0.072852879 | O8: =IFERROR(AVERAGE(D8:L8),0) -> 0.096644792 | P8: =IFERROR(MEDIAN(C8:L8),0) -> 0.10025307
B9: Dividend growth | D9: =IFERROR(HistoricalFS!D41/HistoricalFS!C41-1,0) -> 0.084208811 | E9: =IFERROR(HistoricalFS!E41/HistoricalFS!D41-1,0) -> 0.11650645 | F9: =IFERROR(HistoricalFS!F41/HistoricalFS!E41-1,0) -> 0.76521571 | G9: =IFERROR(HistoricalFS!G41/HistoricalFS!F41-1,0) -> 0.059113555 | H9: =IFERROR(HistoricalFS!H41/HistoricalFS!G41-1,0) -> 0.069767819 | I9: =IFERROR(HistoricalFS!I41/HistoricalFS!H41-1,0) -> 0.34782561 | J9: =IFERROR(HistoricalFS!J41/HistoricalFS!I41-1,0) -> -0.11290335 | K9: =IFERROR(HistoricalFS!K41/HistoricalFS!J41-1,0) -> 0.043636312 | L9: =IFERROR(HistoricalFS!L41/HistoricalFS!K41-1,0) -> 0.010453437 | O9: =IFERROR(AVERAGE(D9:L9),0) -> 0.15375826 | P9: =IFERROR(MEDIAN(C9:L9),0) -> 0.069767819
B11: Gross margin | C11: =IFERROR(HistoricalFS!C13,0) -> 0.84819045 | D11: =IFERROR(HistoricalFS!D13,0) -> 0.83567424 | E11: =IFERROR(HistoricalFS!E13,0) -> 0.86362252 | F11: =IFERROR(HistoricalFS!F13,0) -> 0.87280639 | G11: =IFERROR(HistoricalFS!G13,0) -> 0.87606342 | H11: =IFERROR(HistoricalFS!H13,0) -> 0.88487026 | I11: =IFERROR(HistoricalFS!I13,0) -> 0.87397219 | J11: =IFERROR(HistoricalFS!J13,0) -> 0.87756245 | ... L11: =IFERROR(HistoricalFS!L13,0) -> 0.90159265 | O11: =IFERROR(AVERAGE(C11:L11),0) -> 0.87179917 | P11: =IFERROR(MEDIAN(C11:L11),0) -> 0.8750178
B12: EBITDA margin | C12: =IFERROR(HistoricalFS!C19,0) -> 0.72311984 | D12: =IFERROR(HistoricalFS!D19,0) -> 0.72149769 | E12: =IFERROR(HistoricalFS!E19,0) -> 0.74806008 | F12: =IFERROR(HistoricalFS!F19,0) -> 0.75711442 | G12: =IFERROR(HistoricalFS!G19,0) -> 0.76823892 | H12: =IFERROR(HistoricalFS!H19,0) -> 0.7864553 | I12: =IFERROR(HistoricalFS!I19,0) -> 0.7764999 | J12: =IFERROR(HistoricalFS!J19,0) -> 0.77336375 | ... L12: =IFERROR(HistoricalFS!L19,0) -> 0.79124643 | O12: =IFERROR(AVERAGE(C12:L12),0) -> 0.76227253 | P12: =IFERROR(MEDIAN(C12:L12),0) -> 0.77080133
B13: EBIT margin | C13: =IFERROR((HistoricalFS!C18-HistoricalFS!C24)/HistoricalFS!C6,0) -> 0.69616509 | D13: =IFERROR((HistoricalFS!D18-HistoricalFS!D24)/HistoricalFS!D6,0) -> 0.69304407 | E13: =IFERROR((HistoricalFS!E18-HistoricalFS!E24)/HistoricalFS!E6,0) -> 0.71916843 | F13: =IFERROR((HistoricalFS!F18-HistoricalFS!F24)/HistoricalFS!F6,0) -> 0.72380836 | G13: =IFERROR((HistoricalFS!G18-HistoricalFS!G24)/HistoricalFS!G6,0) -> 0.73483097 | H13: =IFERROR((HistoricalFS!H18-HistoricalFS!H24)/HistoricalFS!H6,0) -> 0.75788867 | I13: =IFERROR((HistoricalFS!I18-HistoricalFS!I24)/HistoricalFS!I6,0) -> 0.7509918 | J13: =IFERROR((HistoricalFS!J18-HistoricalFS!J24)/HistoricalFS!J6,0) -> 0.75101712 | ... L13: =IFERROR((HistoricalFS!L18-HistoricalFS!L24)/HistoricalFS!L6,0) -> 0.76955802 | O13: =IFERROR(AVERAGE(C13:L13),0) -> 0.73517448 | P13: =IFERROR(MEDIAN(C13:L13),0) -> 0.74291139
B14: EBT margin | C14: =IFERROR(HistoricalFS!C28,0) -> 0.69501866 | D14: =IFERROR(HistoricalFS!D28,0) -> 0.69039705 | E14: =IFERROR(HistoricalFS!E28,0) -> 0.71769138 | F14: =IFERROR(HistoricalFS!F28,0) -> 0.72216058 | G14: =IFERROR(HistoricalFS!G28,0) -> 0.7336541 | H14: =IFERROR(HistoricalFS!H28,0) -> 0.75689947 | I14: =IFERROR(HistoricalFS!I28,0) -> 0.7498952 | J14: =IFERROR(HistoricalFS!J28,0) -> 0.7504414 | ... L14: =IFERROR(HistoricalFS!L28,0) -> 0.76847812 | O14: =IFERROR(AVERAGE(C14:L14),0) -> 0.733931 | P14: =IFERROR(MEDIAN(C14:L14),0) -> 0.74177465
B15: Net Profit margin | C15: =IFERROR(HistoricalFS!C34,0) -> 0.5652688 | D15: =IFERROR(HistoricalFS!D34,0) -> 0.55422733 | E15: =IFERROR(HistoricalFS!E34,0) -> 0.58707544 | F15: =IFERROR(HistoricalFS!F34,0) -> 0.63222341 | G15: =IFERROR(HistoricalFS!G34,0) -> 0.64117489 | H15: =IFERROR(HistoricalFS!H34,0) -> 0.67053819 | I15: =IFERROR(HistoricalFS!I34,0) -> 0.65910997 | J15: =IFERROR(HistoricalFS!J34,0) -> 0.65903432 | ... L15: =IFERROR(HistoricalFS!L34,0) -> 0.67952944 | O15: =IFERROR(AVERAGE(C15:L15),0) -> 0.63113773 | P15: =IFERROR(MEDIAN(C15:L15),0) -> 0.6501046
B17: SalesExpenses%sales | C17: =IFERROR(HistoricalFS!C16,0) -> 0.12507061 | D17: =IFERROR(HistoricalFS!D16,0) -> 0.11417655 | E17: =IFERROR(HistoricalFS!E16,0) -> 0.11556244 | F17: =IFERROR(HistoricalFS!F16,0) -> 0.11569196 | G17: =IFERROR(HistoricalFS!G16,0) -> 0.1078245 | H17: =IFERROR(HistoricalFS!H16,0) -> 0.09841496 | I17: =IFERROR(HistoricalFS!I16,0) -> 0.097472286 | J17: =IFERROR(HistoricalFS!J16,0) -> 0.1041987 | ... L17: =IFERROR(HistoricalFS!L16,0) -> 0.11034622 | O17: =IFERROR(AVERAGE(C17:L17),0) -> 0.10952664 | P17: =IFERROR(MEDIAN(C17:L17),0) -> 0.10908536
B18: Depreciation%sales | C18: =IFERROR(HistoricalFS!C25,0) -> 0.026954751 | D18: =IFERROR(HistoricalFS!D25,0) -> 0.028453629 | E18: =IFERROR(HistoricalFS!E25,0) -> 0.028891645 | F18: =IFERROR(HistoricalFS!F25,0) -> 0.033306066 | G18: =IFERROR(HistoricalFS!G25,0) -> 0.033407941 | H18: =IFERROR(HistoricalFS!H25,0) -> 0.028566628 | I18: =IFERROR(HistoricalFS!I25,0) -> 0.025508104 | J18: =IFERROR(HistoricalFS!J25,0) -> 0.022346631 | ... L18: =IFERROR(HistoricalFS!L25,0) -> 0.021688408 | O18: =IFERROR(AVERAGE(C18:L18),0) -> 0.027098051 | P18: =IFERROR(MEDIAN(C18:L18),0) -> 0.02770419
B19: OperatingIncome%sales | C19: =C13 -> 0.69616509 | D19: =D13 -> 0.69304407 | E19: =E13 -> 0.71916843 | F19: =F13 -> 0.72380836 | G19: =G13 -> 0.73483097 | H19: =H13 -> 0.75788867 | I19: =I13 -> 0.7509918 | J19: =J13 -> 0.75101712 | ... L19: =L13 -> 0.76955802 | O19: =IFERROR(AVERAGE(C19:L19),0) -> 0.73517448 | P19: =IFERROR(MEDIAN(C19:L19),0) -> 0.74291139
B21: Return on Capital Employed | C21: =IFERROR((HistoricalFS!C18-HistoricalFS!C24)/(SUM(HistoricalFS!C47:C49)),0) -> 0.64085612 | D21: =IFERROR((HistoricalFS!D18-HistoricalFS!D24)/(SUM(HistoricalFS!D47:D49)),0) -> 0.57306004 | E21: =IFERROR((HistoricalFS!E18-HistoricalFS!E24)/(SUM(HistoricalFS!E47:E49)),0) -> 0.58768837 | F21: =IFERROR((HistoricalFS!F18-HistoricalFS!F24)/(SUM(HistoricalFS!F47:F49)),0) -> 0.54533704 | G21: =IFERROR((HistoricalFS!G18-HistoricalFS!G24)/(SUM(HistoricalFS!G47:G49)),0) -> 0.59711304 | H21: =IFERROR((HistoricalFS!H18-HistoricalFS!H24)/(SUM(HistoricalFS!H47:H49)),0) -> 0.73298465 | I21: =IFERROR((HistoricalFS!I18-HistoricalFS!I24)/(SUM(HistoricalFS!I47:I49)),0) -> 0.76675228 | J21: =IFERROR((HistoricalFS!J18-HistoricalFS!J24)/(SUM(HistoricalFS!J47:J49)),0) -> 0.6819644 | ... L21: =IFERROR((HistoricalFS!L18-HistoricalFS!L24)/(SUM(HistoricalFS!L47:L49)),0) -> 0.81026244 | O21: =IFERROR(AVERAGE(C21:L21),0) -> 0.67450913 | P21: =IFERROR(MEDIAN(C21:L21),0) -> 0.66141026
B22: Retained earnings % | C22: =HistoricalFS!C44 -> 0.76132473 | D22: =HistoricalFS!D44 -> 0.73899269 | E22: =HistoricalFS!E44 -> 0.7516225 | F22: =HistoricalFS!F44 -> 0.60041775 | G22: =HistoricalFS!G44 -> 0.58103692 | H22: =HistoricalFS!H44 -> 0.65149438 | I22: =HistoricalFS!I44 -> 0.58789084 | J22: =HistoricalFS!J44 -> 0.61655887 | ... L22: =HistoricalFS!L44 -> 0.66100714 | O22: =IFERROR(AVERAGE(C22:L22),0) -> 0.65908612 | P22: =IFERROR(MEDIAN(C22:L22),0) -> 0.64600488
B23: Return on equity % | C23: =IFERROR(HistoricalFS!C33/SUM(HistoricalFS!C47:C48),0) -> 0.52087188 | D23: =IFERROR(HistoricalFS!D33/SUM(HistoricalFS!D47:D48),0) -> 0.45858959 | E23: =IFERROR(HistoricalFS!E33/SUM(HistoricalFS!E47:E48),0) -> 0.47985395 | F23: =IFERROR(HistoricalFS!F33/SUM(HistoricalFS!F47:F48),0) -> 0.47835913 | G23: =IFERROR(HistoricalFS!G33/SUM(HistoricalFS!G47:G48),0) -> 0.52334767 | H23: =IFERROR(HistoricalFS!H33/SUM(HistoricalFS!H47:H48),0) -> 0.65109453 | I23: =IFERROR(HistoricalFS!I33/SUM(HistoricalFS!I47:I48),0) -> 0.67592024 | J23: =IFERROR(HistoricalFS!J33/SUM(HistoricalFS!J47:J48),0) -> 0.60087616 | ... L23: =IFERROR(HistoricalFS!L33/SUM(HistoricalFS!L47:L48),0) -> 0.73914489 | O23: =IFERROR(AVERAGE(C23:L23),0) -> 0.58413818 | P23: =IFERROR(MEDIAN(C23:L23),0) -> 0.56211192
B24: Self sustained growth rate | C24: =IFERROR(C22*C23,0) -> 0.39655264 | D24: =IFERROR(D22*D23,0) -> 0.33889436 | E24: =IFERROR(E22*E23,0) -> 0.36066903 | F24: =IFERROR(F22*F23,0) -> 0.28721532 | G24: =IFERROR(G22*G23,0) -> 0.30408432 | H24: =IFERROR(H22*H23,0) -> 0.42418442 | I24: =IFERROR(I22*I23,0) -> 0.39736732 | J24: =IFERROR(J22*J23,0) -> 0.37047553 | ... L24: =IFERROR(L22*L23,0) -> 0.48858005 | O24: =IFERROR(AVERAGE(C24:L24),0) -> 0.38249178 | P24: =IFERROR(MEDIAN(C24:L24),0) -> 0.38351408
B25: Interest Coverage ratio | C25: =IFERROR((HistoricalFS!C18-HistoricalFS!C24)/HistoricalFS!C21,0) -> 607.24679 | D25: =IFERROR((HistoricalFS!D18-HistoricalFS!D24)/HistoricalFS!D21,0) -> 261.82097 | E25: =IFERROR((HistoricalFS!E18-HistoricalFS!E24)/HistoricalFS!E21,0) -> 486.89496 | F25: =IFERROR((HistoricalFS!F18-HistoricalFS!F24)/HistoricalFS!F21,0) -> 439.26309 | G25: =IFERROR((HistoricalFS!G18-HistoricalFS!G24)/HistoricalFS!G21,0) -> 624.3902 | H25: =IFERROR((HistoricalFS!H18-HistoricalFS!H24)/HistoricalFS!H21,0) -> 766.15786 | I25: =IFERROR((HistoricalFS!I18-HistoricalFS!I24)/HistoricalFS!I21,0) -> 684.8349 | J25: =IFERROR((HistoricalFS!J18-HistoricalFS!J24)/HistoricalFS!J21,0) -> 1304.4758 | ... L25: =IFERROR((HistoricalFS!L18-HistoricalFS!L24)/HistoricalFS!L21,0) -> 712.61958 | O25: =IFERROR(AVERAGE(C25:L25),0) -> 715.02348 | P25: =IFERROR(MEDIAN(C25:L25),0) -> 654.61255
B27: Debtor Turnover ratio | C27: =IFERROR(HistoricalFS!C6/HistoricalFS!C59,0) -> 17.284797 | D27: =IFERROR(HistoricalFS!D6/HistoricalFS!D59,0) -> 16.19845 | E27: =IFERROR(HistoricalFS!E6/HistoricalFS!E59,0) -> 11.979238 | F27: =IFERROR(HistoricalFS!F6/HistoricalFS!F59,0) -> 19.273399 | G27: =IFERROR(HistoricalFS!G6/HistoricalFS!G59,0) -> 19.689591 | H27: =IFERROR(HistoricalFS!H6/HistoricalFS!H59,0) -> 24.633226 | I27: =IFERROR(HistoricalFS!I6/HistoricalFS!I59,0) -> 23.990173 | J27: =IFERROR(HistoricalFS!J6/HistoricalFS!J59,0) -> 16.874063 | ... L27: =IFERROR(HistoricalFS!L6/HistoricalFS!L59,0) -> 20.104821 | O27: =IFERROR(AVERAGE(C27:L27),0) -> 18.598721 | P27: =IFERROR(MEDIAN(C27:L27),0) -> 18.279098
B28: Creditor Turnover ratio | C28: =IFERROR(HistoricalFS!C9/HistoricalFS!C50,0) -> 0.68779205 | D28: =IFERROR(HistoricalFS!D9/HistoricalFS!D50,0) -> 0.61050633 | E28: =IFERROR(HistoricalFS!E9/HistoricalFS!E50,0) -> 0.52384358 | F28: =IFERROR(HistoricalFS!F9/HistoricalFS!F50,0) -> 0.53416485 | G28: =IFERROR(HistoricalFS!G9/HistoricalFS!G50,0) -> 0.46450509 | H28: =IFERROR(HistoricalFS!H9/HistoricalFS!H50,0) -> 0.48181528 | I28: =IFERROR(HistoricalFS!I9/HistoricalFS!I50,0) -> 0.54599607 | J28: =IFERROR(HistoricalFS!J9/HistoricalFS!J50,0) -> 0.49089033 | ... L28: =IFERROR(HistoricalFS!L9/HistoricalFS!L50,0) -> 0.41435568 | O28: =IFERROR(AVERAGE(C28:L28),0) -> 0.52493908 | P28: =IFERROR(MEDIAN(C28:L28),0) -> 0.50968257
B29: Inventory Turnover ratio | C29: =IFERROR(HistoricalFS!C9/HistoricalFS!C60,0) -> 0.79995688 | D29: =IFERROR(HistoricalFS!D9/HistoricalFS!D60,0) -> 0.9525943 | E29: =IFERROR(HistoricalFS!E9/HistoricalFS!E60,0) -> 0.83877851 | F29: =IFERROR(HistoricalFS!F9/HistoricalFS!F60,0) -> 0.70746329 | G29: =IFERROR(HistoricalFS!G9/HistoricalFS!G60,0) -> 0.58716034 | H29: =IFERROR(HistoricalFS!H9/HistoricalFS!H60,0) -> 0.64266325 | I29: =IFERROR(HistoricalFS!I9/HistoricalFS!I60,0) -> 0.7592939 | J29: =IFERROR(HistoricalFS!J9/HistoricalFS!J60,0) -> 0.58768392 | ... L29: =IFERROR(HistoricalFS!L9/HistoricalFS!L60,0) -> 0.41675598 | O29: =IFERROR(AVERAGE(C29:L29),0) -> 0.68528496 | P29: =IFERROR(MEDIAN(C29:L29),0) -> 0.67506327
B30: Fixed Asset Turnover ratio | C30: =IFERROR(HistoricalFS!C6/HistoricalFS!C53,0) -> 2.6908896 | D30: =IFERROR(HistoricalFS!D6/AVERAGE(HistoricalFS!C53:D53),0) -> 2.6805904 | E30: =IFERROR(HistoricalFS!E6/AVERAGE(HistoricalFS!D53:E53),0) -> 2.6931516 | F30: =IFERROR(HistoricalFS!F6/AVERAGE(HistoricalFS!E53:F53),0) -> 2.4040238 | G30: =IFERROR(HistoricalFS!G6/AVERAGE(HistoricalFS!F53:G53),0) -> 2.1886451 | H30: =IFERROR(HistoricalFS!H6/AVERAGE(HistoricalFS!G53:H53),0) -> 2.5518389 | I30: =IFERROR(HistoricalFS!I6/AVERAGE(HistoricalFS!H53:I53),0) -> 2.8320679 | J30: =IFERROR(HistoricalFS!J6/AVERAGE(HistoricalFS!I53:J53),0) -> 2.5313976 | K30: =IFERROR(HistoricalFS!K6/AVERAGE(HistoricalFS!J53:K53),0) -> 3.0265488 | L30: =IFERROR(HistoricalFS!L6/AVERAGE(HistoricalFS!K53:L53),0) -> 3.5528403 | O30: =IFERROR(AVERAGE(C30:L30),0) -> 2.7151994 | P30: =IFERROR(MEDIAN(C30:L30),0) -> 2.68574
B31: Capital Turnover ratio | C31: =IFERROR(HistoricalFS!C6/SUM(HistoricalFS!C47:C48),0) -> 0.92145874 | D31: =IFERROR(HistoricalFS!D6/SUM(HistoricalFS!D47:D48),0) -> 0.82743952 | E31: =IFERROR(HistoricalFS!E6/SUM(HistoricalFS!E47:E48),0) -> 0.81736336 | F31: =IFERROR(HistoricalFS!F6/SUM(HistoricalFS!F47:F48),0) -> 0.7566299 | G31: =IFERROR(HistoricalFS!G6/SUM(HistoricalFS!G47:G48),0) -> 0.81623233 | H31: =IFERROR(HistoricalFS!H6/SUM(HistoricalFS!H47:H48),0) -> 0.97100291 | I31: =IFERROR(HistoricalFS!I6/SUM(HistoricalFS!I47:I48),0) -> 1.0255045 | J31: =IFERROR(HistoricalFS!J6/SUM(HistoricalFS!J47:J48),0) -> 0.91175245 | ... L31: =IFERROR(HistoricalFS!L6/SUM(HistoricalFS!L47:L48),0) -> 1.0877305 | O31: =IFERROR(AVERAGE(C31:L31),0) -> 0.92107002 | P31: =IFERROR(MEDIAN(C31:L31),0) -> 0.9166056
B33: (in days)
B34: Debtors days | C34: =IFERROR(365/C27,0) -> 21.116823 | D34: =IFERROR(365/D27,0) -> 22.53302 | E34: =IFERROR(365/E27,0) -> 30.469383 | F34: =IFERROR(365/F27,0) -> 18.938019 | G34: =IFERROR(365/G27,0) -> 18.537714 | H34: =IFERROR(365/H27,0) -> 14.817385 | I34: =IFERROR(365/I27,0) -> 15.214563 | J34: =IFERROR(365/J27,0) -> 21.630831 | ... L34: =IFERROR(365/L27,0) -> 18.154849 | O34: =IFERROR(AVERAGE(C34:L34),0) -> 20.428305 | P34: =IFERROR(MEDIAN(C34:L34),0) -> 20.027421
B35: Payable days | C35: =IFERROR(365/C28,0) -> 530.68365 | D35: =IFERROR(365/D28,0) -> 597.86439 | E35: =IFERROR(365/E28,0) -> 696.77288 | F35: =IFERROR(365/F28,0) -> 683.30966 | G35: =IFERROR(365/G28,0) -> 785.78256 | H35: =IFERROR(365/H28,0) -> 757.55174 | I35: =IFERROR(365/I28,0) -> 668.50298 | J35: =IFERROR(365/J28,0) -> 743.54693 | ... L35: =IFERROR(365/L28,0) -> 880.88571 | O35: =IFERROR(AVERAGE(C35:L35),0) -> 708.14981 | P35: =IFERROR(MEDIAN(C35:L35),0) -> 716.68524
B36: Inventory days | C36: =IFERROR(365/C29,0) -> 456.2746 | D36: =IFERROR(365/D29,0) -> 383.16417 | E36: =IFERROR(365/E29,0) -> 435.1566 | F36: =IFERROR(365/F29,0) -> 515.92783 | G36: =IFERROR(365/G29,0) -> 621.63599 | H36: =IFERROR(365/H29,0) -> 567.94907 | I36: =IFERROR(365/I29,0) -> 480.70977 | J36: =IFERROR(365/J29,0) -> 621.08216 | ... L36: =IFERROR(365/L29,0) -> 875.81226 | O36: =IFERROR(AVERAGE(C36:L36),0) -> 560.89177 | P36: =IFERROR(MEDIAN(C36:L36),0) -> 541.93845
B37: Cash Conversion Cycle | C37: =IFERROR(SUM(C36,C34)-C35,0) -> -53.292236 | D37: =IFERROR(SUM(D36,D34)-D35,0) -> -192.16721 | E37: =IFERROR(SUM(E36,E34)-E35,0) -> -231.1469 | F37: =IFERROR(SUM(F36,F34)-F35,0) -> -148.44381 | G37: =IFERROR(SUM(G36,G34)-G35,0) -> -145.60885 | H37: =IFERROR(SUM(H36,H34)-H35,0) -> -174.78528 | I37: =IFERROR(SUM(I36,I34)-I35,0) -> -172.57864 | J37: =IFERROR(SUM(J36,J34)-J35,0) -> -100.83394 | ... L37: =IFERROR(SUM(L36,L34)-L35,0) -> 13.081401 | O37: =IFERROR(AVERAGE(C37:L37),0) -> -126.82974 | P37: =IFERROR(MEDIAN(C37:L37),0) -> -147.02633
B39: CFO/Sales | C39: =IFERROR(HistoricalFS!C79/HistoricalFS!C6,0) -> 0.0072952422 | D39: =IFERROR(HistoricalFS!D79/HistoricalFS!D6,0) -> 0.0069967184 | E39: =IFERROR(HistoricalFS!E79/HistoricalFS!E6,0) -> 0.0042615182 | F39: =IFERROR(HistoricalFS!F79/HistoricalFS!F6,0) -> 0.0067425695 | G39: =IFERROR(HistoricalFS!G79/HistoricalFS!G6,0) -> 0.0074100466 | H39: =IFERROR(HistoricalFS!H79/HistoricalFS!H6,0) -> 0.0073378411 | I39: =IFERROR(HistoricalFS!I79/HistoricalFS!I6,0) -> 0.0069515897 | J39: =IFERROR(HistoricalFS!J79/HistoricalFS!J6,0) -> 0.007743044 | ... L39: =IFERROR(HistoricalFS!L79/HistoricalFS!L6,0) -> 0.011081751 | O39: =IFERROR(AVERAGE(C39:L39),0) -> 0.0074516165 | P39: =IFERROR(MEDIAN(C39:L39),0) -> 0.0073165417
B40: CFO/Total Assets | C40: =IFERROR(HistoricalFS!C79/HistoricalFS!C64,0) -> 0.0055815631 | D40: =IFERROR(HistoricalFS!D79/HistoricalFS!D64,0) -> 0.0047321892 | E40: =IFERROR(HistoricalFS!E79/HistoricalFS!E64,0) -> 0.0028715188 | F40: =IFERROR(HistoricalFS!F79/HistoricalFS!F64,0) -> 0.0043072923 | G40: =IFERROR(HistoricalFS!G79/HistoricalFS!G64,0) -> 0.0049484306 | H40: =IFERROR(HistoricalFS!H79/HistoricalFS!H64,0) -> 0.0057645459 | I40: =IFERROR(HistoricalFS!I79/HistoricalFS!I64,0) -> 0.0057438481 | J40: =IFERROR(HistoricalFS!J79/HistoricalFS!J64,0) -> 0.005732722 | ... L40: =IFERROR(HistoricalFS!L79/HistoricalFS!L64,0) -> 0.0093338972 | O40: =IFERROR(AVERAGE(C40:L40),0) -> 0.0056458961 | P40: =IFERROR(MEDIAN(C40:L40),0) -> 0.0056571425
B41: CFO/Total Debt | C41: =IFERROR(HistoricalFS!C79/HistoricalFS!C49,0) -> 6.824147 | D41: =IFERROR(HistoricalFS!D79/HistoricalFS!D49,0) -> 8.4632517 | E41: =IFERROR(HistoricalFS!E79/HistoricalFS!E49,0) -> 15.327381 | F41: =IFERROR(HistoricalFS!F79/HistoricalFS!F49,0) -> 1.2002163 | G41: =IFERROR(HistoricalFS!G79/HistoricalFS!G49,0) -> 1.3477089 | H41: =IFERROR(HistoricalFS!H79/HistoricalFS!H49,0) -> 1.7839962 | I41: =IFERROR(HistoricalFS!I79/HistoricalFS!I49,0) -> 1.6109005 | J41: =IFERROR(HistoricalFS!J79/HistoricalFS!J49,0) -> 1.7335135 | ... L41: =IFERROR(HistoricalFS!L79/HistoricalFS!L49,0) -> 0.36430935 | O41: =IFERROR(AVERAGE(C41:L41),0) -> 4.0957385 | P41: =IFERROR(MEDIAN(C41:L41),0) -> 1.7587548

Sheet Forecasting 
B3: ='Data Sheet'!B1& " - "& 'Data Sheet'!A17&" Forecasting " -> ITC LTD - Sales Forecasting | G3: ='Data Sheet'!B1&" - "& HistoricalFS!B18&" Forecasting " -> ITC LTD - EBITDA Forecasting | L3: ='Data Sheet'!B1& " - "&HistoricalFS!B38& " Forecasting " -> ITC LTD - Earnings Per Share Forecasting
B4: Year Weight | C4: Year | D4: Sales | E4: Sales Growth | G4: Year Weight | H4: Year | I4: EBITDA | J4: EBITDA Growth | L4: Year Weight | M4: Year | N4: EPS | O4: EPS Growth
B5: 1 | C5: ='Data Sheet'!$B$16 -> 42825 | D5: {=TRANSPOSE('Data Sheet'!B17:K17)} -> 42767.6 | G5: 1 | H5: ='Data Sheet'!B16 -> 42825 | I5: {=TRANSPOSE(HistoricalFS!C18:L18)} -> 30926.1 | L5: 1 | M5: ='Data Sheet'!B16 -> 42825 | N5: {=IFERROR(TRANSPOSE(HistoricalFS!C38:L38),0)} -> 19.901534
B6: =B5+1 -> 2 | C6: =C5+365 -> 43190 | D6: 43448.94 | E6: =IFERROR(D6/D5-1,0) -> 0.015931219 | G6: =G5+1 -> 2 | H6: =H5+365 -> 43190 | I6: 31348.31 | J6: =IFERROR(I6/I5-1,0) -> 0.013652223 | L6: =L5+1 -> 2 | M6: =M5+365 -> 43190 | N6: 19.731234 | O6: =IFERROR(N6/N5-1,0) -> -0.0085571498
B7: =B6+1 -> 3 | C7: =C6+365 -> 43555 | D7: 48339.58 | E7: =IFERROR(D7/D6-1,0) -> 0.11256063 | G7: =G6+1 -> 3 | H7: =H6+365 -> 43555 | I7: 36160.91 | J7: =IFERROR(I7/I6-1,0) -> 0.15352024 | L7: =L6+1 -> 3 | M7: =M6+365 -> 43555 | N7: 23.150262 | O7: =IFERROR(N7/N6-1,0) -> 0.17327998
B8: =B7+1 -> 4 | C8: =C7+365 -> 43920 | D8: 49387.7 | E8: =IFERROR(D8/D7-1,0) -> 0.021682439 | G8: =G7+1 -> 4 | H8: =H7+365 -> 43920 | I8: 37392.14 | J8: =IFERROR(I8/I7-1,0) -> 0.034048645 | L8: =L7+1 -> 4 | M8: =M7+365 -> 43920 | N8: 25.401523 | O8: =IFERROR(N8/N7-1,0) -> 0.097245598
B9: =B8+1 -> 5 | C9: =C8+365 -> 44285 | D9: 49257.45 | E9: =IFERROR(D9/D8-1,0) -> -0.0026372963 | G9: =G8+1 -> 5 | H9: =H8+365 -> 44285 | I9: 37841.49 | J9: =IFERROR(I9/I8-1,0) -> 0.012017231 | L9: =L8+1 -> 5 | M9: =M8+365 -> 44285 | N9: 25.658586 | O9: =IFERROR(N9/N8-1,0) -> 0.010119976
B10: =B9+1 -> 6 | C10: =C9+365 -> 44650 | D10: 60644.54 | E10: =IFERROR(D10/D9-1,0) -> 0.23117498 | G10: =G9+1 -> 6 | H10: =H9+365 -> 44650 | I10: 47694.22 | J10: =IFERROR(I10/I9-1,0) -> 0.26036845 | L10: =L9+1 -> 6 | M10: =M9+365 -> 44650 | N10: 32.998044 | O10: =IFERROR(N10/N9-1,0) -> 0.28604299
B11: =B10+1 -> 7 | C11: =C10+365 -> 45015 | D11: 70919.03 | E11: =IFERROR(D11/D10-1,0) -> 0.16942152 | G11: =G10+1 -> 7 | H11: =H10+365 -> 45015 | I11: 55068.62 | J11: =IFERROR(I11/I10-1,0) -> 0.15461832 | L11: =L10+1 -> 7 | M11: =M10+365 -> 45015 | N11: 37.611394 | O11: =IFERROR(N11/N10-1,0) -> 0.13980675
B12: =B11+1 -> 8 | C12: =C11+365 -> 45380 | D12: 67931.94 | E12: =IFERROR(D12/D11-1,0) -> -0.042119724 | G12: =G11+1 -> 8 | H12: =H11+365 -> 45380 | I12: 52536.1 | J12: =IFERROR(I12/I11-1,0) -> -0.045988441 | L12: =L11+1 -> 8 | M12: =M11+365 -> 45380 | N12: 35.859476 | O12: =IFERROR(N12/N11-1,0) -> -0.046579439
B13: =B12+1 -> 9 | C13: =C12+365 -> 45745 | D13: 75323.34 | E13: =IFERROR(D13/D12-1,0) -> 0.10880596 | G13: =G12+1 -> 9 | H13: =H12+365 -> 45745 | I13: 58535.95 | J13: =IFERROR(I13/I12-1,0) -> 0.11420433 | L13: =L12+1 -> 9 | M13: =M12+365 -> 45745 | N13: 39.918252 | O13: =IFERROR(N13/N12-1,0) -> 0.1131856
B14: =B13+1 -> 10 | C14: =C13+365 -> 46110 | D14: 78868.4 | E14: =IFERROR(D14/D13-1,0) -> 0.047064562 | G14: =G13+1 -> 10 | H14: =H13+365 -> 46110 | I14: 62404.34 | J14: =IFERROR(I14/I13-1,0) -> 0.066085713 | L14: =L13+1 -> 10 | M14: =M13+365 -> 46110 | N14: 42.773774 | O14: =IFERROR(N14/N13-1,0) -> 0.071534236
B15: =B14+1 -> 11 | C15: =C14+365 -> 46475 | D15: =IFERROR(FORECAST(B15,$D$5:$D$14,$B$5:$B$14),0) -> 82754.548 | E15: =IFERROR(D15/D14-1,0) -> 0.049273828 | G15: =G14+1 -> 11 | H15: =H14+365 -> 46475 | I15: =IFERROR(FORECAST(G15,$I$5:$I$14,$G$5:$G$14),0) -> 65603.343 | J15: =IFERROR(I15/I14-1,0) -> 0.051262514 | L15: =L14+1 -> 11 | M15: =M14+365 -> 46475 | N15: =IFERROR(FORECAST(L15,$N$5:$N$14,$L$5:$L$14),0) -> 45.456222 | O15: =IFERROR(N15/N14-1,0) -> 0.062712449
B16: =B15+1 -> 12 | C16: =C15+365 -> 46840 | D16: =IFERROR(FORECAST(B16,$D$5:$D$14,$B$5:$B$14),0) -> 87130.129 | E16: =IFERROR(D16/D15-1,0) -> 0.052874207 | G16: =G15+1 -> 12 | H16: =H15+365 -> 46840 | I16: =IFERROR(FORECAST(G16,$I$5:$I$14,$G$5:$G$14),0) -> 69351.075 | J16: =IFERROR(I16/I15-1,0) -> 0.057127148 | L16: =L15+1 -> 12 | M16: =M15+365 -> 46840 | N16: =IFERROR(FORECAST(L16,$N$5:$N$14,$L$5:$L$14),0) -> 48.211825 | O16: =IFERROR(N16/N15-1,0) -> 0.06062102
B17: =B16+1 -> 13 | C17: =C16+365 -> 47205 | D17: =IFERROR(FORECAST(B17,$D$5:$D$14,$B$5:$B$14),0) -> 91505.71 | E17: =IFERROR(D17/D16-1,0) -> 0.050218921 | G17: =G16+1 -> 13 | H17: =H16+365 -> 47205 | I17: =IFERROR(FORECAST(G17,$I$5:$I$14,$G$5:$G$14),0) -> 73098.807 | J17: =IFERROR(I17/I16-1,0) -> 0.054039997 | L17: =L16+1 -> 13 | M17: =M16+365 -> 47205 | N17: =IFERROR(FORECAST(L17,$N$5:$N$14,$L$5:$L$14),0) -> 50.967427 | O17: =IFERROR(N17/N16-1,0) -> 0.057156156
B18: =B17+1 -> 14 | C18: =C17+365 -> 47570 | D18: =IFERROR(FORECAST(B18,$D$5:$D$14,$B$5:$B$14),0) -> 95881.291 | E18: =IFERROR(D18/D17-1,0) -> 0.047817574 | G18: =G17+1 -> 14 | H18: =H17+365 -> 47570 | I18: =IFERROR(FORECAST(G18,$I$5:$I$14,$G$5:$G$14),0) -> 76846.539 | J18: =IFERROR(I18/I17-1,0) -> 0.051269399 | L18: =L17+1 -> 14 | M18: =M17+365 -> 47570 | N18: =IFERROR(FORECAST(L18,$N$5:$N$14,$L$5:$L$14),0) -> 53.72303 | O18: =IFERROR(N18/N17-1,0) -> 0.054065954
B19: =B18+1 -> 15 | C19: =C18+365 -> 47935 | D19: =IFERROR(FORECAST(B19,$D$5:$D$14,$B$5:$B$14),0) -> 100256.87 | E19: =IFERROR(D19/D18-1,0) -> 0.0456354 | G19: =G18+1 -> 15 | H19: =H18+365 -> 47935 | I19: =IFERROR(FORECAST(G19,$I$5:$I$14,$G$5:$G$14),0) -> 80594.271 | J19: =IFERROR(I19/I18-1,0) -> 0.048769039 | L19: =L18+1 -> 15 | M19: =M18+365 -> 47935 | N19: =IFERROR(FORECAST(L19,$N$5:$N$14,$L$5:$L$14),0) -> 56.478632 | O19: =IFERROR(N19/N18-1,0) -> 0.051292762

Sheet Data Sheet
A1: COMPANY NAME | B1: ITC LTD | E1: =IF(B2<>B3, "A NEW VERSION OF THE WORKSHEET IS AVAILABLE", "")
A2: LATEST VERSION | B2: 2.1 | E2: PLEASE DO NOT MAKE ANY CHANGES TO THIS SHEET
A3: CURRENT VERSION | B3: 2.1
A5: META
A6: Number of shares | B6: =IF(B9>0, B9/B8, 0) -> 1252.9468
A7: Face Value | B7: 1
A8: Current Price | B8: 280.8
A9: Market Capitalization | B9: 351827.47
A15: PROFIT & LOSS
A16: Report Date | B16: 42825 | C16: 43190 | D16: 43555 | E16: 43921 | F16: 44286 | G16: 44651 | H16: 45016 | I16: 45382 | J16: 45747 | K16: 46112
A17: Sales | B17: 42767.6 | C17: 43448.94 | D17: 48339.58 | E17: 49387.7 | F17: 49257.45 | G17: 60644.54 | H17: 70919.03 | I17: 67931.94 | J17: 75323.34 | K17: 78868.4
A18: Raw Material Cost | B18: 15456.59 | C18: 14827.72 | D18: 17623.52 | E18: 18048.6 | F18: 20776.71 | G18: 27071.07 | H18: 29364.36 | I18: 27348.57 | J18: 32704.37 | K18: 35098.34
A19: Change in Inventory | B19: -592.57 | C19: -1027.76 | D19: 203.19 | E19: 703.13 | F19: 645.27 | G19: 686 | H19: 358.59 | I19: 367.77 | J19: 725.65 | K19: 2550.46
A20: Power and Fuel | B20: 584.33 | C20: 653.5 | D20: 746.73 | E20: 780.85 | F20: 699.56 | G20: 889.77 | H20: 1232.34 | I20: 952.9 | J20: 975.35 | K20: 947.71
A21: Other Mfr. Exp | B21: 1683.9 | C21: 1697.62 | D21: 1871.01 | E21: 1908.29 | F21: 1587.18 | G21: 1887.67 | H21: 2327.8 | I21: 2183.76 | J21: 2345.36 | K21: 2582.48
A22: Employee Cost | B22: 3631.73 | C22: 3760.9 | D22: 4177.88 | E22: 4295.79 | F22: 4463.33 | G22: 4890.55 | H22: 5736.22 | I22: 5548.53 | J22: 6169.78 | K22: 6781.5
A23: Selling and admin | B23: 4179.74 | C23: 3954.87 | D23: 4546.39 | E23: 4488.63 | F23: 4236.77 | G23: 4858.38 | H23: 5604.08 | I23: 5312.45 | J23: 5793.29 | K23: 6377.95
A24: Other Expenses | B24: 1169.23 | C24: 1005.98 | D24: 1039.85 | E24: 1225.13 | F24: 1074.39 | G24: 1109.95 | H24: 1308.56 | I24: 1765.97 | J24: 2229.26 | K24: 2324.88
A25: Other Income | B25: 1758.63 | C25: 2239.81 | D25: 2080.44 | E25: 2417.32 | F25: 2576.95 | G25: 1909.72 | H25: 2097.64 | I25: 3330.45 | J25: 17802.75 | K25: 2523.09
A26: Depreciation | B26: 1152.79 | C26: 1236.28 | D26: 1396.61 | E26: 1644.91 | F26: 1645.59 | G26: 1732.41 | H26: 1809.01 | I26: 1518.05 | J26: 1646.32 | K26: 1710.53
A27: Interest | B27: 49.03 | C27: 115.01 | D27: 71.4 | E27: 81.38 | F27: 57.97 | G27: 59.99 | H27: 77.77 | I27: 39.11 | J27: 45.06 | K27: 85.17
... A31: Dividend Amount | B31: 5770.02 | C31: 6285.21 | D31: 7048.7 | E31: 12476.58 | F31: 13231.96 | G31: 14171.8 | H31: 19263.4 | I31: 17166.46 | J31: 17957.73 | K31: 18167.78
A40: Quarters
A41: Report Date | B41: 45291 | C41: 45382 | D41: 45473 | E41: 45565 | F41: 45657 | G41: 45747 | H41: 45838 | I41: 45930 | J41: 46022 | K41: 46112
A42: Sales | B42: 17195.24 | C42: 17037.8 | D42: 17777.81 | E42: 19990.36 | F42: 18790.17 | G42: 18765 | H42: 21494.79 | I42: 19501.63 | J42: 20047.3 | K42: 17824.68
A43: Expenses | B43: 10985.01 | C43: 10735.73 | D43: 11232.97 | E43: 13438.28 | F43: 12428.27 | G43: 12245.61 | H43: 14678.32 | I43: 12806.94 | J43: 13164.78 | K43: 10900.45
A44: Other Income | B44: 820.26 | C44: 868 | D44: 771.13 | E44: 690.31 | F44: 803.4 | G44: 15391.28 | H44: 750.97 | I44: 738.84 | J44: 321.85 | K44: 699.52
A45: Depreciation | B45: 384.04 | C45: 385.09 | D45: 403.13 | E45: 416.18 | F45: 415.98 | G45: 411.03 | H45: 422.96 | I45: 434.8 | J45: 430.82 | K45: 421.95
A46: Interest | B46: 11.94 | C46: 10.72 | D46: 9.6 | E46: 14.73 | F46: 9.82 | G46: 10.91 | H46: 16.47 | I46: 20.05 | J46: 19.47 | K46: 29.18
A47: Profit before tax | B47: 6634.51 | C47: 6774.26 | D47: 6903.24 | E47: 6811.48 | F47: 6739.5 | G47: 21488.73 | H47: 7128.01 | I47: 6978.68 | J47: 6754.08 | K47: 7172.62
A48: Tax | B48: 1227.99 | C48: 1583.55 | D48: 1726.25 | E48: 1757.05 | F48: 1726.32 | G48: 1680.85 | H48: 1784.6 | I48: 1792.13 | J48: 1735.63 | K48: 1702.88
A49: Net profit | B49: 5335.23 | C49: 5120.55 | D49: 5091.59 | E49: 4992.87 | F49: 4934.8 | G49: 19727.37 | H49: 5244.2 | I49: 5126.11 | J49: 4931.19 | K49: 5387.97
A50: Operating Profit | B50: 6210.23 | C50: 6302.07 | D50: 6544.84 | E50: 6552.08 | F50: 6361.9 | G50: 6519.39 | H50: 6816.47 | I50: 6694.69 | J50: 6882.52 | K50: 6924.23
A55: BALANCE SHEET
A56: Report Date | B56: 42825 | C56: 43190 | D56: 43555 | E56: 43921 | F56: 44286 | G56: 44651 | H56: 45016 | I56: 45382 | J56: 45747 | K56: 46112
A57: Equity Share Capital | B57: 1214.74 | C57: 1220.43 | D57: 1225.86 | E57: 1229.22 | F57: 1230.88 | G57: 1232.33 | H57: 1242.8 | I57: 1248.47 | J57: 1251.41 | K57: 1252.95
A58: Reserves | B58: 45198.19 | C58: 51289.68 | D58: 57915.01 | E58: 64044.04 | F58: 59116.46 | G58: 61223.24 | H58: 67912.46 | I58: 73258.53 | J58: 68778.64 | K58: 71254.35
A59: Borrowings | B59: 45.72 | C59: 35.92 | D59: 13.44 | E59: 277.45 | F59: 270.83 | G59: 249.44 | H59: 306.04 | I59: 303.43 | J59: 284.54 | K59: 2399.06
A60: Other Liabilities | B60: 9439.67 | C60: 11694.85 | D60: 12584.73 | E60: 11760.04 | F60: 13142.59 | G60: 14491.01 | H60: 16369.66 | I60: 16943.54 | J60: 17688.11 | K60: 18730.84
A61: Total | B61: 55898.32 | C61: 64240.88 | D61: 71739.04 | E61: 77310.75 | F61: 73760.76 | G61: 77196.02 | H61: 85830.96 | I61: 91753.97 | J61: 88002.7 | K61: 93637.2
...

Sheet Cash Flow Data
C2: 42064 | D2: 42430 | E2: 42795 | F2: 43160 | G2: 43525 | H2: 43891 | I2: 44256 | J2: 44621 | K2: 44986 | L2: 45352 | M2: 45717 | N2: 46082
B3: Cash from Operating Activity - | C3: 243 | D3: 418 | E3: 312 | F3: 305 | G3: 206 | H3: 333 | I3: 365 | J3: 444 | K3: 493 | L3: 526 | M3: 655 | N3: 873
B4: Profit from operations | C4: 325 | D4: 514 | E4: 462 | F4: 402 | G4: 329 | H4: 343 | I4: 458 | J4: 679 | K4: 758 | L4: 826 | M4: 901 | N4: 1198
B5: Receivables | C5: -26 | D5: -63 | E5: -33 | F5: -15 | G5: -15 | H5: 10 | I5: -30 | J5: -37 | K5: -112 | L5: -55 | M5: -93 | N5: -237
B6: Inventory | C6: 0 | D6: 0 | E6: 0 | F6: 0 | G6: 0 | H6: 0 | I6: 0 | J6: 0 | K6: 0 | L6: 0 | M6: 0 | N6: 0
B7: Payables | C7: 1 | D7: 32 | E7: -12 | F7: 18 | G7: -3 | H7: 0 | I7: 7 | J7: 15 | K7: 20 | L7: 11 | M7: 21 | N7: 53
B8: Loans Advances | C8: -8 | D8: 0 | E8: 0 | F8: 0 | G8: 0 | H8: 0 | I8: 0 | J8: 0 | K8: 0 | L8: 0 | M8: 0 | N8: 0
B9: Other WC items | C9: 19 | D9: 48 | E9: -3 | F9: -6 | G9: -12 | H9: 39 | I9: 31 | J9: -48 | K9: 5 | L9: -84 | M9: -11 | N9: 85
B10: Working capital changes | C10: -15 | D10: 16 | E10: -47 | F10: -3 | G10: -30 | H10: 49 | I10: 7 | J10: -70 | K10: -87 | L10: -128 | M10: -82 | N10: -99
B11: Direct taxes | C11: -68 | D11: 0 | E11: 0 | F11: 0 | G11: 0 | H11: 0 | I11: 0 | J11: -164 | K11: -178 | L11: -172 | M11: -164 | N11: -225
B12: Other operating items | C12: 0 | D12: -113 | E12: -103 | F12: -95 | G12: -93 | H12: -59 | I12: -100 | J12: 0 | K12: 0 | L12: 0 | M12: 0 | N12: 0
B13: Cash from Investing Activity - | C13: -62 | D13: -167 | E13: -175 | F13: 26 | G13: -230 | H13: 24 | I13: -2 | J13: 44 | K13: -55 | L13: -483 | M13: 143 | N13: -141
B14: Fixed assets purchased | C14: -61 | D14: -53 | E14: -30 | F14: -42 | G14: -52 | H14: -34 | I14: -39 | J14: -61 | K14: -91 | L14: -67 | M14: -121 | N14: -119
... B34: CFO/OP | C34: 0.98 | D34: 0.87 | E34: 0.68 | F34: 0.83 | G34: 0.67 | H34: 1.02 | I34: 0.81 | J34: 0.92 | K34: 0.93 | L34: 0.9 | M34: 1.01 | N34: 1.04
