Workbook
Name UPDATE: 'Data Sheet'!$E$1

Sheet HistoricalFS
B2: ="Historical Statement - " & 'Data Sheet'!B1 -> Historical Statement - ECLERX SERVICES LTD
B3: Years | C3: =IFERROR('Data Sheet'!B16,0) -> 42825 | D3: =IFERROR('Data Sheet'!C16,0) -> 43190 | E3: =IFERROR('Data Sheet'!D16,0) -> 43555 | F3: =IFERROR('Data Sheet'!E16,0) -> 43921 | G3: =IFERROR('Data Sheet'!F16,0) -> 44286 | H3: =IFERROR('Data Sheet'!G16,0) -> 44651 | I3: =IFERROR('Data Sheet'!H16,0) -> 45016 | J3: =IFERROR('Data Sheet'!I16,0) -> 45382 | ... L3: =IFERROR('Data Sheet'!K16,0) -> 46112 | M3: LTM
A5: # | B5: Income Statement
B6: Sales | C6: =IFERROR('Data Sheet'!B17,0) -> 1330.03 | D6: =IFERROR('Data Sheet'!C17,0) -> 1365.06 | E6: =IFERROR('Data Sheet'!D17,0) -> 1430.59 | F6: =IFERROR('Data Sheet'!E17,0) -> 1437.57 | G6: =IFERROR('Data Sheet'!F17,0) -> 1564.49 | H6: =IFERROR('Data Sheet'!G17,0) -> 2160.35 | I6: =IFERROR('Data Sheet'!H17,0) -> 2647.9 | J6: =IFERROR('Data Sheet'!I17,0) -> 2925.54 | ... L6: =IFERROR('Data Sheet'!K17,0) -> 4117.03 | M6: =IFERROR(SUM('Data Sheet'!H42:K42),0) -> 4117.03
B7: Sales Growth | C7: - | D7: =D6/C6-1 -> 0.026337752 | E7: =E6/D6-1 -> 0.048005216 | F7: =F6/E6-1 -> 0.0048791058 | G7: =G6/F6-1 -> 0.088287875 | H7: =H6/G6-1 -> 0.38086533 | I7: =I6/H6-1 -> 0.22568102 | J7: =J6/I6-1 -> 0.1048529 | K7: =K6/J6-1 -> 0.15051238 | L7: =L6/K6-1 -> 0.22316964 | M7: -
B9: COS | C9: =IFERROR(SUM('Data Sheet'!B20:B22)-1*'Data Sheet'!B19,0) -> 667.47 | D9: =IFERROR(SUM('Data Sheet'!C20:C22)-1*'Data Sheet'!C19,0) -> 781.61 | E9: =IFERROR(SUM('Data Sheet'!D20:D22)-1*'Data Sheet'!D19,0) -> 879.96 | F9: =IFERROR(SUM('Data Sheet'!E20:E22)-1*'Data Sheet'!E19,0) -> 930.88 | G9: =IFERROR(SUM('Data Sheet'!F20:F22)-1*'Data Sheet'!F19,0) -> 956.15 | H9: =IFERROR(SUM('Data Sheet'!G20:G22)-1*'Data Sheet'!G19,0) -> 1327.6 | I9: =IFERROR(SUM('Data Sheet'!H20:H22)-1*'Data Sheet'!H19,0) -> 1670.43 | J9: =IFERROR(SUM('Data Sheet'!I20:I22)-1*'Data Sheet'!I19,0) -> 1867.16 | ... L9: =IFERROR(SUM('Data Sheet'!K20:K22)-1*'Data Sheet'!K19,0) -> 2524.53 | M9: =IFERROR(SUM('Data Sheet'!H43:K43),0) -> 3065.58
B10: COS % Sales | C10: =C9/C6 -> 0.50184582 | D10: =D9/D6 -> 0.57258289 | E10: =E9/E6 -> 0.61510286 | F10: =F9/F6 -> 0.64753716 | G10: =G9/G6 -> 0.61115763 | H10: =H9/H6 -> 0.61453005 | I10: =I9/I6 -> 0.63085086 | J10: =J9/J6 -> 0.63822747 | ... M10: =M9/M6 -> 0.74460959
B12: Gross Profit | C12: =C6-C9 -> 662.56 | D12: =D6-D9 -> 583.45 | E12: =E6-E9 -> 550.63 | F12: =F6-F9 -> 506.69 | G12: =G6-G9 -> 608.34 | H12: =H6-H9 -> 832.75 | I12: =I6-I9 -> 977.47 | J12: =J6-J9 -> 1058.38 | ... M12: =M6-M9 -> 1051.45
B13: Gross Margins | C13: =C12/C6 -> 0.49815418 | D13: =D12/D6 -> 0.42741711 | E13: =E12/E6 -> 0.38489714 | F13: =F12/F6 -> 0.35246284 | G13: =G12/G6 -> 0.38884237 | H13: =H12/H6 -> 0.38546995 | I13: =I12/I6 -> 0.36914914 | J13: =J12/J6 -> 0.36177253 | ... M13: =M12/M6 -> 0.25539041
B15: Selling & General Expenses | C15: =IFERROR(SUM('Data Sheet'!B23:B24),0) -> 201.29 | D15: =IFERROR(SUM('Data Sheet'!C23:C24),0) -> 215.95 | E15: =IFERROR(SUM('Data Sheet'!D23:D24),0) -> 241.78 | F15: =IFERROR(SUM('Data Sheet'!E23:E24),0) -> 180.54 | G15: =IFERROR(SUM('Data Sheet'!F23:F24),0) -> 158.81 | H15: =IFERROR(SUM('Data Sheet'!G23:G24),0) -> 170.7 | I15: =IFERROR(SUM('Data Sheet'!H23:H24),0) -> 254.19 | J15: =IFERROR(SUM('Data Sheet'!I23:I24),0) -> 282.62 | ... L15: =IFERROR(SUM('Data Sheet'!K23:K24),0) -> 541.05
B16: SG&A % Sales | C16: =C15/C6 -> 0.15134245 | D16: =D15/D6 -> 0.15819817 | E16: =E15/E6 -> 0.16900719 | F16: =F15/F6 -> 0.12558693 | G16: =G15/G6 -> 0.10150912 | H16: =H15/H6 -> 0.079014974 | I16: =I15/I6 -> 0.095996828 | J16: =J15/J6 -> 0.096604388 | ... M16: =M15/M6 -> 0
B18: EBITDA | C18: =C12-C15 -> 461.27 | D18: =D12-D15 -> 367.5 | E18: =E12-E15 -> 308.85 | F18: =F12-F15 -> 326.15 | G18: =G12-G15 -> 449.53 | H18: =H12-H15 -> 662.05 | I18: =I12-I15 -> 723.28 | J18: =J12-J15 -> 775.76 | ... M18: =M12-M15 -> 1051.45
B19: EBITDA % Sales | C19: =C18/C6 -> 0.34681173 | D19: =D18/D6 -> 0.26921894 | E19: =E18/E6 -> 0.21588995 | F19: =F18/F6 -> 0.22687591 | G19: =G18/G6 -> 0.28733325 | H19: =H18/H6 -> 0.30645497 | I19: =I18/I6 -> 0.27315231 | J19: =J18/J6 -> 0.26516814 | ... M19: =M18/M6 -> 0.25539041
B21: Interest | C21: =IFERROR(('Data Sheet'!B27),0) -> 1.57 | D21: =IFERROR(('Data Sheet'!C27),0) -> 1.17 | E21: =IFERROR(('Data Sheet'!D27),0) -> 1.27 | F21: =IFERROR(('Data Sheet'!E27),0) -> 20.16 | G21: =IFERROR(('Data Sheet'!F27),0) -> 21.42 | H21: =IFERROR(('Data Sheet'!G27),0) -> 22.76 | I21: =IFERROR(('Data Sheet'!H27),0) -> 22.19 | J21: =IFERROR(('Data Sheet'!I27),0) -> 24.45 | ... L21: =IFERROR(('Data Sheet'!K27),0) -> 42.14 | M21: =IFERROR(SUM('Data Sheet'!H46:K46),0) -> 42.14
B22: Interest % Sales | C22: =C21/C6 -> 0.0011804245 | D22: =D21/D6 -> 0.00085710518 | E22: =E21/E6 -> 0.00088774562 | F22: =F21/F6 -> 0.014023665 | G22: =G21/G6 -> 0.013691363 | H22: =H21/H6 -> 0.01053533 | I22: =I21/I6 -> 0.0083802258 | J22: =J21/J6 -> 0.0083574314 | ... M22: =M21/M6 -> 0.010235534
B24: Depreciation | C24: =IFERROR(('Data Sheet'!B26),0) -> 51.8 | D24: =IFERROR(('Data Sheet'!C26),0) -> 48.24 | E24: =IFERROR(('Data Sheet'!D26),0) -> 44.69 | F24: =IFERROR(('Data Sheet'!E26),0) -> 70.9 | G24: =IFERROR(('Data Sheet'!F26),0) -> 81.59 | H24: =IFERROR(('Data Sheet'!G26),0) -> 103.19 | I24: =IFERROR(('Data Sheet'!H26),0) -> 114.01 | J24: =IFERROR(('Data Sheet'!I26),0) -> 125.77 | ... L24: =IFERROR(('Data Sheet'!K26),0) -> 175.37 | M24: =IFERROR(SUM('Data Sheet'!H45:K45),0) -> 175.37
B25: Depreciation % Sales | C25: =C24/C6 -> 0.03894649 | D25: =D24/D6 -> 0.035339106 | E25: =E24/E6 -> 0.031238859 | F25: =F24/F6 -> 0.049319337 | G25: =G24/G6 -> 0.05215118 | H25: =H24/H6 -> 0.047765408 | I25: =I24/I6 -> 0.043056762 | J25: =J24/J6 -> 0.042990354 | ... M25: =M24/M6 -> 0.04259624
B27: Earnings Before Tax | C27: =IFERROR(C18-SUM(C21,C24),0) -> 407.9 | D27: =IFERROR(D18-SUM(D21,D24),0) -> 318.09 | E27: =IFERROR(E18-SUM(E21,E24),0) -> 262.89 | F27: =IFERROR(F18-SUM(F21,F24),0) -> 235.09 | G27: =IFERROR(G18-SUM(G21,G24),0) -> 346.52 | H27: =IFERROR(H18-SUM(H21,H24),0) -> 536.1 | I27: =IFERROR(I18-SUM(I21,I24),0) -> 587.08 | J27: =IFERROR(J18-SUM(J21,J24),0) -> 625.54 | ... M27: =IFERROR(M18-SUM(M21,M24),0) -> 833.94
B28: EBT % Sales | C28: =C27/C6 -> 0.30668481 | D28: =D27/D6 -> 0.23302272 | E28: =E27/E6 -> 0.18376334 | F28: =F27/F6 -> 0.16353291 | G28: =G27/G6 -> 0.22149071 | H28: =H27/H6 -> 0.24815423 | I28: =I27/I6 -> 0.22171532 | J28: =J27/J6 -> 0.21382035 | ... M28: =M27/M6 -> 0.20255864
B30: Tax | C30: =IFERROR('Data Sheet'!B29,0) -> 81.91 | D30: =IFERROR('Data Sheet'!C29,0) -> 89.58 | E30: =IFERROR('Data Sheet'!D29,0) -> 83.17 | F30: =IFERROR('Data Sheet'!E29,0) -> 71.55 | G30: =IFERROR('Data Sheet'!F29,0) -> 97.8 | H30: =IFERROR('Data Sheet'!G29,0) -> 142.73 | I30: =IFERROR('Data Sheet'!H29,0) -> 163.8 | J30: =IFERROR('Data Sheet'!I29,0) -> 177.61 | ... L30: =IFERROR('Data Sheet'!K29,0) -> 228.65 | M30: =IFERROR(SUM('Data Sheet'!H48:K48),0) -> 228.64
B31: Effective Tax rate | C31: =C30/C27 -> 0.20080902 | D31: =D30/D27 -> 0.28161841 | E31: =E30/E27 -> 0.31636806 | F31: =F30/F27 -> 0.30435152 | G31: =G30/G27 -> 0.28223479 | H31: =H30/H27 -> 0.26623764 | I31: =I30/I27 -> 0.27900797 | J31: =J30/J27 -> 0.28393068 | ... M31: =M30/M27 -> 0.27416841
B33: Net Profit | C33: =IFERROR((C27-C30),0) -> 325.99 | D33: =IFERROR((D27-D30),0) -> 228.51 | E33: =IFERROR((E27-E30),0) -> 179.72 | F33: =IFERROR((F27-F30),0) -> 163.54 | G33: =IFERROR((G27-G30),0) -> 248.72 | H33: =IFERROR((H27-H30),0) -> 393.37 | I33: =IFERROR((I27-I30),0) -> 423.28 | J33: =IFERROR((J27-J30),0) -> 447.93 | ... M33: =IFERROR((M27-M30),0) -> 605.3
B34: Net Margin | C34: =C33/C6 -> 0.24509973 | D34: =D33/D6 -> 0.16739924 | E34: =E33/E6 -> 0.12562649 | F34: =F33/F6 -> 0.11376142 | G34: =G33/G6 -> 0.15897833 | H34: =H33/H6 -> 0.18208624 | I34: =I33/I6 -> 0.15985498 | J34: =J33/J6 -> 0.1531102 | ... M34: =M33/M6 -> 0.14702346
B36: No. of Equity Shares O/S | C36: =IFERROR('Data Sheet'!B93,0) -> 11.94 | D36: =IFERROR('Data Sheet'!C93,0) -> 11.6 | E36: =IFERROR('Data Sheet'!D93,0) -> 11.61 | F36: =IFERROR('Data Sheet'!E93,0) -> 11.1 | G36: =IFERROR('Data Sheet'!F93,0) -> 10.47 | H36: =IFERROR('Data Sheet'!G93,0) -> 10.16 | I36: =IFERROR('Data Sheet'!H93,0) -> 9.81 | J36: =IFERROR('Data Sheet'!I93,0) -> 9.81 | ... L36: =IFERROR('Data Sheet'!K93,0) -> 9.41 | M36: =L36 -> 9.41
B38: Earnings Per Share | C38: =IFERROR(C33/C36,0) -> 27.302345 | D38: =IFERROR(D33/D36,0) -> 19.699138 | E38: =IFERROR(E33/E36,0) -> 15.479759 | F38: =IFERROR(F33/F36,0) -> 14.733333 | G38: =IFERROR(G33/G36,0) -> 23.755492 | H38: =IFERROR(H33/H36,0) -> 38.71752 | I38: =IFERROR(I33/I36,0) -> 43.147808 | J38: =IFERROR(J33/J36,0) -> 45.66055 | ... M38: =IFERROR(M33/M36,0) -> 64.325186
B39: EPS growth % | D39: =IFERROR((D38/C38-1),0) -> -0.27848183 | E39: =IFERROR((E38/D38-1),0) -> -0.21419105 | F39: =IFERROR((F38/E38-1),0) -> -0.048219452 | G39: =IFERROR((G38/F38-1),0) -> 0.6123637 | H39: =IFERROR((H38/G38-1),0) -> 0.62983448 | I39: =IFERROR((I38/H38-1),0) -> 0.11442594 | J39: =IFERROR((J38/I38-1),0) -> 0.058235683 | K39: =IFERROR((K38/J38-1),0) -> 0.045007876 | ... M39: =IFERROR((M38/L38-1),0) -> 1.6521006e-05
B41: Dividends Per Share | C41: =IFERROR(('Data Sheet'!B31/C36),0) -> 0.33249581 | D41: =IFERROR(('Data Sheet'!C31/D36),0) -> 0.32844828 | E41: =IFERROR(('Data Sheet'!D31/E36),0) -> 0.3255814 | F41: =IFERROR(('Data Sheet'!E31/F36),0) -> 0.32522523 | G41: =IFERROR(('Data Sheet'!F31/G36),0) -> 0.32473734 | H41: =IFERROR(('Data Sheet'!G31/H36),0) -> 0.3257874 | I41: =IFERROR(('Data Sheet'!H31/I36),0) -> 0.48929664 | J41: =IFERROR(('Data Sheet'!I31/J36),0) -> 0.49133537 | ... M41: =IFERROR(('Data Sheet'!L31/M36),0) -> 0
B42: Dividend Payout Ratio | C42: =IFERROR((C41/C38),0) -> 0.012178288 | D42: =IFERROR((D41/D38),0) -> 0.016673231 | E42: =IFERROR((E41/E38),0) -> 0.021032718 | F42: =IFERROR((F41/F38),0) -> 0.02207411 | G42: =IFERROR((G41/G38),0) -> 0.01366999 | H42: =IFERROR((H41/H38),0) -> 0.0084144698 | I42: =IFERROR((I41/I38),0) -> 0.011340011 | J42: =IFERROR((J41/J38),0) -> 0.01076061 | ... M42: =IFERROR((M41/M38),0) -> 0
B44: Retained Earnings | C44: =IFERROR(IF(C38>C41,1-C42,0),0) -> 0.98782171 | D44: =IFERROR(IF(D38>D41,1-D42,0),0) -> 0.98332677 | E44: =IFERROR(IF(E38>E41,1-E42,0),0) -> 0.97896728 | F44: =IFERROR(IF(F38>F41,1-F42,0),0) -> 0.97792589 | G44: =IFERROR(IF(G38>G41,1-G42,0),0) -> 0.98633001 | H44: =IFERROR(IF(H38>H41,1-H42,0),0) -> 0.99158553 | I44: =IFERROR(IF(I38>I41,1-I42,0),0) -> 0.98865999 | J44: =IFERROR(IF(J38>J41,1-J42,0),0) -> 0.98923939 | ... M44: =IFERROR(IF(M38>M41,1-M42,0),0) -> 1
A46: # | B46: Balance Sheet
B47: Equity Share Capital | C47: =IFERROR('Data Sheet'!B57,0) -> 39.71 | D47: =IFERROR('Data Sheet'!C57,0) -> 38.14 | E47: =IFERROR('Data Sheet'!D57,0) -> 37.79 | F47: =IFERROR('Data Sheet'!E57,0) -> 36.1 | G47: =IFERROR('Data Sheet'!F57,0) -> 34.01 | H47: =IFERROR('Data Sheet'!G57,0) -> 33.1 | I47: =IFERROR('Data Sheet'!H57,0) -> 48.03 | J47: =IFERROR('Data Sheet'!I57,0) -> 48.23 | ... L47: =IFERROR('Data Sheet'!K57,0) -> 92.03
B48: Reserves | C48: =IFERROR('Data Sheet'!B58,0) -> 1175.64 | D48: =IFERROR('Data Sheet'!C58,0) -> 1166.61 | E48: =IFERROR('Data Sheet'!D58,0) -> 1343.51 | F48: =IFERROR('Data Sheet'!E58,0) -> 1270.12 | G48: =IFERROR('Data Sheet'!F58,0) -> 1466.81 | H48: =IFERROR('Data Sheet'!G58,0) -> 1534.49 | I48: =IFERROR('Data Sheet'!H58,0) -> 1666.84 | J48: =IFERROR('Data Sheet'!I58,0) -> 2199.27 | ... L48: =IFERROR('Data Sheet'!K58,0) -> 2469.37
B49: Borrowings | C49: =IFERROR('Data Sheet'!B59,0) -> 1.06 | D49: =IFERROR('Data Sheet'!C59,0) -> 6.34 | E49: =IFERROR('Data Sheet'!D59,0) -> 1.67 | F49: =IFERROR('Data Sheet'!E59,0) -> 156.6 | G49: =IFERROR('Data Sheet'!F59,0) -> 174.73 | H49: =IFERROR('Data Sheet'!G59,0) -> 163.12 | I49: =IFERROR('Data Sheet'!H59,0) -> 193.56 | J49: =IFERROR('Data Sheet'!I59,0) -> 265.74 | ... L49: =IFERROR('Data Sheet'!K59,0) -> 384.96
B50: Other Liabilities | C50: =IFERROR('Data Sheet'!B60,0) -> 181.73 | D50: =IFERROR('Data Sheet'!C60,0) -> 207.8 | E50: =IFERROR('Data Sheet'!D60,0) -> 201.01 | F50: =IFERROR('Data Sheet'!E60,0) -> 260.2 | G50: =IFERROR('Data Sheet'!F60,0) -> 315 | H50: =IFERROR('Data Sheet'!G60,0) -> 324.48 | I50: =IFERROR('Data Sheet'!H60,0) -> 365.47 | J50: =IFERROR('Data Sheet'!I60,0) -> 406.15 | ... L50: =IFERROR('Data Sheet'!K60,0) -> 750.66
B51: Total Liabilities | C51: =IFERROR('Data Sheet'!B61,0) -> 1398.14 | D51: =IFERROR('Data Sheet'!C61,0) -> 1418.89 | E51: =IFERROR('Data Sheet'!D61,0) -> 1583.98 | F51: =IFERROR('Data Sheet'!E61,0) -> 1723.02 | G51: =IFERROR('Data Sheet'!F61,0) -> 1990.55 | H51: =IFERROR('Data Sheet'!G61,0) -> 2055.19 | I51: =IFERROR('Data Sheet'!H61,0) -> 2273.9 | J51: =IFERROR('Data Sheet'!I61,0) -> 2919.39 | ... L51: =IFERROR('Data Sheet'!K61,0) -> 3697.02
B53: Fixed Assets Net Block | C53: =IFERROR('Data Sheet'!B62,0) -> 325.06 | D53: =IFERROR('Data Sheet'!C62,0) -> 343.43 | E53: =IFERROR('Data Sheet'!D62,0) -> 347.91 | F53: =IFERROR('Data Sheet'!E62,0) -> 479.74 | G53: =IFERROR('Data Sheet'!F62,0) -> 728.03 | H53: =IFERROR('Data Sheet'!G62,0) -> 712.56 | I53: =IFERROR('Data Sheet'!H62,0) -> 772.51 | J53: =IFERROR('Data Sheet'!I62,0) -> 842.95 | ... L53: =IFERROR('Data Sheet'!K62,0) -> 1053.94
B54: Capital Work in Progress | C54: =IFERROR('Data Sheet'!B63,0) -> 1.85 | D54: =IFERROR('Data Sheet'!C63,0) -> 0.09 | E54: =IFERROR('Data Sheet'!D63,0) -> 0.17 | F54: =IFERROR('Data Sheet'!E63,0) -> 0.8 | G54: =IFERROR('Data Sheet'!F63,0) -> 0.48 | H54: =IFERROR('Data Sheet'!G63,0) -> 2.17 | I54: =IFERROR('Data Sheet'!H63,0) -> 20.82 | J54: =IFERROR('Data Sheet'!I63,0) -> 0.77 | ... L54: =IFERROR('Data Sheet'!K63,0) -> 4.92
B55: Investments | C55: =IFERROR('Data Sheet'!B64,0) -> 251.64 | D55: =IFERROR('Data Sheet'!C64,0) -> 165.27 | E55: =IFERROR('Data Sheet'!D64,0) -> 286.26 | F55: =IFERROR('Data Sheet'!E64,0) -> 436.79 | G55: =IFERROR('Data Sheet'!F64,0) -> 228.62 | H55: =IFERROR('Data Sheet'!G64,0) -> 195.88 | I55: =IFERROR('Data Sheet'!H64,0) -> 274.51 | J55: =IFERROR('Data Sheet'!I64,0) -> 406.5 | ... L55: =IFERROR('Data Sheet'!K64,0) -> 307.85
B56: Other Assets | C56: =IFERROR('Data Sheet'!B65-SUM('Data Sheet'!B67:B69),0) -> 249.85 | D56: =IFERROR('Data Sheet'!C65-SUM('Data Sheet'!C67:C69),0) -> 236.54 | E56: =IFERROR('Data Sheet'!D65-SUM('Data Sheet'!D67:D69),0) -> 255.14 | F56: =IFERROR('Data Sheet'!E65-SUM('Data Sheet'!E67:E69),0) -> 233.11 | G56: =IFERROR('Data Sheet'!F65-SUM('Data Sheet'!F67:F69),0) -> 249.22 | H56: =IFERROR('Data Sheet'!G65-SUM('Data Sheet'!G67:G69),0) -> 321.15 | I56: =IFERROR('Data Sheet'!H65-SUM('Data Sheet'!H67:H69),0) -> 337.19 | J56: =IFERROR('Data Sheet'!I65-SUM('Data Sheet'!I67:I69),0) -> 480.43 | ... L56: =IFERROR('Data Sheet'!K65-SUM('Data Sheet'!K67:K69),0) -> 925.25
B57: Total Non Current Asset | C57: =IFERROR(SUM(C53:C56),0) -> 828.4 | D57: =IFERROR(SUM(D53:D56),0) -> 745.33 | E57: =IFERROR(SUM(E53:E56),0) -> 889.48 | F57: =IFERROR(SUM(F53:F56),0) -> 1150.44 | G57: =IFERROR(SUM(G53:G56),0) -> 1206.35 | H57: =IFERROR(SUM(H53:H56),0) -> 1231.76 | I57: =IFERROR(SUM(I53:I56),0) -> 1405.03 | J57: =IFERROR(SUM(J53:J56),0) -> 1730.65 | ... L57: =IFERROR(SUM(L53:L56),0) -> 2291.96
...

Sheet Data Sheet
A1: COMPANY NAME | B1: ECLERX SERVICES LTD | E1: =IF(B2<>B3, "A NEW VERSION OF THE WORKSHEET IS AVAILABLE", "")
A2: LATEST VERSION | B2: 2.1 | E2: PLEASE DO NOT MAKE ANY CHANGES TO THIS SHEET
A3: CURRENT VERSION | B3: 2.1
A5: META
A6: Number of shares | B6: =IF(B9>0, B9/B8, 0) -> 9.4050712
A7: Face Value | B7: 10
A8: Current Price | B8: 1979.8
A9: Market Capitalization | B9: 18620.16
A15: PROFIT & LOSS
A16: Report Date | B16: 42825 | C16: 43190 | D16: 43555 | E16: 43921 | F16: 44286 | G16: 44651 | H16: 45016 | I16: 45382 | J16: 45747 | K16: 46112
A17: Sales | B17: 1330.03 | C17: 1365.06 | D17: 1430.59 | E17: 1437.57 | F17: 1564.49 | G17: 2160.35 | H17: 2647.9 | I17: 2925.54 | J17: 3365.87 | K17: 4117.03
A18: Raw Material Cost
A19: Change in Inventory
A20: Power and Fuel | B20: 10.02 | C20: 9.37 | D20: 10.64 | E20: 9.36 | F20: 8.75 | G20: 9.61 | H20: 13.38 | I20: 16.27 | J20: 19.82
A21: Other Mfr. Exp | B21: 63.84 | C21: 79.7 | D21: 82.25 | E21: 67.07 | F21: 61.84 | G21: 122.23 | H21: 147.29 | I21: 112.27 | J21: 146.05
A22: Employee Cost | B22: 593.61 | C22: 692.54 | D22: 787.07 | E22: 854.45 | F22: 885.56 | G22: 1195.76 | H22: 1509.76 | I22: 1738.62 | J22: 2065.92 | K22: 2524.53
A23: Selling and admin | B23: 183.77 | C23: 204.89 | D23: 230.33 | E23: 169.91 | F23: 136.48 | G23: 164.36 | H23: 246.33 | I23: 271.87 | J23: 300.43
A24: Other Expenses | B24: 17.52 | C24: 11.06 | D24: 11.45 | E24: 10.63 | F24: 22.33 | G24: 6.34 | H24: 7.86 | I24: 10.75 | J24: 24.34 | K24: 541.05
A25: Other Income | B25: 27.93 | C25: 61.43 | D25: 48.59 | E25: 45.42 | F25: 34.1 | G25: 24.39 | H25: 65.91 | I25: 63.8 | J25: 86.53 | K25: 101.18
A26: Depreciation | B26: 51.8 | C26: 48.24 | D26: 44.69 | E26: 70.9 | F26: 81.59 | G26: 103.19 | H26: 114.01 | I26: 125.77 | J26: 141.19 | K26: 175.37
A27: Interest | B27: 1.57 | C27: 1.17 | D27: 1.27 | E27: 20.16 | F27: 21.42 | G27: 22.76 | H27: 22.19 | I27: 24.45 | J27: 36.12 | K27: 42.14
A28: Profit before tax | B28: 435.83 | C28: 379.52 | D28: 311.48 | E28: 280.51 | F28: 380.62 | G28: 560.49 | H28: 652.99 | I28: 689.34 | J28: 718.53 | K28: 935.12
A29: Tax | B29: 81.91 | C29: 89.58 | D29: 83.17 | E29: 71.55 | F29: 97.8 | G29: 142.73 | H29: 163.8 | I29: 177.61 | J29: 177.27 | K29: 228.65
A30: Net profit | B30: 354.03 | C30: 289.98 | D30: 228.26 | E30: 208.98 | F30: 282.56 | G30: 417.4 | H30: 488.82 | I30: 511.46 | J30: 541.09 | K30: 706.21
A31: Dividend Amount | B31: 3.97 | C31: 3.81 | D31: 3.78 | E31: 3.61 | F31: 3.4 | G31: 3.31 | H31: 4.8 | I31: 4.82 | J31: 4.7 | K31: 9.2
A40: Quarters
A41: Report Date | B41: 45291 | C41: 45382 | D41: 45473 | E41: 45565 | F41: 45657 | G41: 45747 | H41: 45838 | I41: 45930 | J41: 46022 | K41: 46112
A42: Sales | B42: 752.76 | C42: 766.53 | D42: 781.92 | E42: 831.84 | F42: 853.82 | G42: 898.29 | H42: 934.56 | I42: 1004.85 | J42: 1070.33 | K42: 1107.29
A43: Expenses | B43: 545.53 | C43: 571 | D43: 615.55 | E43: 616.18 | F43: 646.34 | G43: 679.71 | H43: 714.03 | I43: 733.78 | J43: 794.07 | K43: 823.7
A44: Other Income | B44: 18.95 | C44: 23.05 | D44: 20.91 | E44: 13.12 | F44: 20.58 | G44: 31.92 | H44: 14.11 | I44: 27.24 | J44: 30.07 | K44: 29.76
A45: Depreciation | B45: 33.53 | C45: 33.53 | D45: 31.65 | E45: 32.8 | F45: 35.78 | G45: 40.96 | H45: 36.9 | I45: 42.5 | J45: 46.31 | K45: 49.66
A46: Interest | B46: 5.86 | C46: 5.58 | D46: 7.72 | E46: 8.12 | F46: 8.28 | G46: 10.78 | H46: 9.69 | I46: 10.8 | J46: 9.91 | K46: 11.74
A47: Profit before tax | B47: 186.79 | C47: 179.47 | D47: 147.91 | E47: 187.86 | F47: 184 | G47: 198.76 | H47: 188.05 | I47: 245.01 | J47: 250.11 | K47: 251.95
A48: Tax | B48: 47.73 | C48: 49.58 | D48: 35.87 | E48: 48.36 | F48: 46.8 | G48: 46.24 | H48: 46.5 | I48: 61.54 | J48: 58.3 | K48: 62.3
A49: Net profit | B49: 138.63 | C49: 130.53 | D49: 111.61 | E49: 140.25 | F49: 137.07 | G49: 152.16 | H49: 141.68 | I49: 183.19 | J49: 191.98 | K49: 189.36
A50: Operating Profit | B50: 207.23 | C50: 195.53 | D50: 166.37 | E50: 215.66 | F50: 207.48 | G50: 218.58 | H50: 220.53 | I50: 271.07 | J50: 276.26 | K50: 283.59
A55: BALANCE SHEET
A56: Report Date | B56: 42825 | C56: 43190 | D56: 43555 | E56: 43921 | F56: 44286 | G56: 44651 | H56: 45016 | I56: 45382 | J56: 45747 | K56: 46112
A57: Equity Share Capital | B57: 39.71 | C57: 38.14 | D57: 37.79 | E57: 36.1 | F57: 34.01 | G57: 33.1 | H57: 48.03 | I57: 48.23 | J57: 46.96 | K57: 92.03
A58: Reserves | B58: 1175.64 | C58: 1166.61 | D58: 1343.51 | E58: 1270.12 | F58: 1466.81 | G58: 1534.49 | H58: 1666.84 | I58: 2199.27 | J58: 2258.8 | K58: 2469.37
...

Sheet Cash Flow Data
C2: 42064 | D2: 42430 | E2: 42795 | F2: 43160 | G2: 43525 | H2: 43891 | I2: 44256 | J2: 44621 | K2: 44986 | L2: 45352 | M2: 45717 | N2: 46082
B3: Cash from Operating Activity - | C3: 243 | D3: 418 | E3: 312 | F3: 305 | G3: 206 | H3: 333 | I3: 365 | J3: 444 | K3: 493 | L3: 526 | M3: 655 | N3: 873
B4: Profit from operations | C4: 325 | D4: 514 | E4: 462 | F4: 402 | G4: 329 | H4: 343 | I4: 458 | J4: 679 | K4: 758 | L4: 826 | M4: 901 | N4: 1198
B5: Receivables | C5: -26 | D5: -63 | E5: -33 | F5: -15 | G5: -15 | H5: 10 | I5: -30 | J5: -37 | K5: -112 | L5: -55 | M5: -93 | N5: -237
B6: Inventory | C6: 0 | D6: 0 | E6: 0 | F6: 0 | G6: 0 | H6: 0 | I6: 0 | J6: 0 | K6: 0 | L6: 0 | M6: 0 | N6: 0
B7: Payables | C7: 1 | D7: 32 | E7: -12 | F7: 18 | G7: -3 | H7: 0 | I7: 7 | J7: 15 | K7: 20 | L7: 11 | M7: 21 | N7: 53
B8: Loans Advances | C8: -8 | D8: 0 | E8: 0 | F8: 0 | G8: 0 | H8: 0 | I8: 0 | J8: 0 | K8: 0 | L8: 0 | M8: 0 | N8: 0
B9: Other WC items | C9: 19 | D9: 48 | E9: -3 | F9: -6 | G9: -12 | H9: 39 | I9: 31 | J9: -48 | K9: 5 | L9: -84 | M9: -11 | N9: 85
B10: Working capital changes | C10: -15 | D10: 16 | E10: -47 | F10: -3 | G10: -30 | H10: 49 | I10: 7 | J10: -70 | K10: -87 | L10: -128 | M10: -82 | N10: -99
B11: Direct taxes | C11: -68 | D11: 0 | E11: 0 | F11: 0 | G11: 0 | H11: 0 | I11: 0 | J11: -164 | K11: -178 | L11: -172 | M11: -164 | N11: -225
B12: Other operating items | C12: 0 | D12: -113 | E12: -103 | F12: -95 | G12: -93 | H12: -59 | I12: -100 | J12: 0 | K12: 0 | L12: 0 | M12: 0 | N12: 0
B13: Cash from Investing Activity - | C13: -62 | D13: -167 | E13: -175 | F13: 26 | G13: -230 | H13: 24 | I13: -2 | J13: 44 | K13: -55 | L13: -483 | M13: 143 | N13: -141
B14: Fixed assets purchased | C14: -61 | D14: -53 | E14: -30 | F14: -42 | G14: -52 | H14: -34 | I14: -39 | J14: -61 | K14: -91 | L14: -67 | M14: -121 | N14: -119
... B34: CFO/OP | C34: 0.98 | D34: 0.87 | E34: 0.68 | F34: 0.83 | G34: 0.67 | H34: 1.02 | I34: 0.81 | J34: 0.92 | K34: 0.93 | L34: 0.9 | M34: 1.01 | N34: 1.04
